<?xml version="1.0" encoding="utf-8"?>
<!-- This URDF was automatically created by SolidWorks to URDF Exporter! Originally created by Stephen Brawner (brawner@gmail.com) 
     Commit Version: 1.6.0-4-g7f85cfe  Build Version: 1.6.7995.38578
     For more information, please see http://wiki.ros.org/sw_urdf_exporter -->
<robot
  name="full_assemandframe01.SLDASM">
  <link
    name="body">
    <inertial>
      <origin
        xyz="-0.00041783 -0.062352 -0.011079"
        rpy="0 0 0" />
      <mass
        value="1.0275" />
      <inertia
        ixx="0.00096224"
        ixy="-1.7543E-09"
        ixz="-1.3676E-09"
        iyy="0.0014276"
        iyz="-7.2992E-06"
        izz="0.0010373" />
    </inertial>
    <visual>
      <origin
        xyz="0 0 0"
        rpy="0 0 0" />
      <geometry>
        <mesh
          filename="package://meshes/body.STL" />
      </geometry>
      <material
        name="">
        <color
          rgba="0.79216 0.81961 0.93333 1" />
      </material>
    </visual>
    <collision>
      <origin
        xyz="0 0 0"
        rpy="0 0 0" />
      <geometry>
        <mesh
          filename="package://meshes/body.STL" />
      </geometry>
    </collision>
  </link>
  <link
    name="R2">
    <inertial>
      <origin
        xyz="5.1195E-12 -0.007935 0.0049359"
        rpy="0 0 0" />
      <mass
        value="0.0059458" />
      <inertia
        ixx="2.941E-06"
        ixy="-2.483E-16"
        ixz="-3.9623E-15"
        iyy="2.9244E-06"
        iyz="-3.8274E-08"
        izz="9.8493E-07" />
    </inertial>
    <visual>
      <origin
        xyz="0 0 0"
        rpy="0 0 0" />
      <geometry>
        <mesh
          filename="package://meshes/R2.STL" />
      </geometry>
      <material
        name="">
        <color
          rgba="0.79216 0.81961 0.93333 1" />
      </material>
    </visual>
    <collision>
      <origin
        xyz="0 0 0"
        rpy="0 0 0" />
      <geometry>
        <mesh
          filename="package://meshes/R2.STL" />
      </geometry>
    </collision>
  </link>
  <joint
    name="JR1"
    type="continuous">
    <origin
      xyz="-0.049 0.010409 -0.13257"
      rpy="1.5739 0 0" />
    <parent
      link="body" />
    <child
      link="R2" />
    <axis
      xyz="0 1 0" />
  </joint>
  <link
    name="R3">
    <inertial>
      <origin
        xyz="-2.3368E-05 -0.01515 -0.020816"
        rpy="0 0 0" />
      <mass
        value="0.15544" />
      <inertia
        ixx="5.5826E-05"
        ixy="-8.8929E-07"
        ixz="-1.7363E-21"
        iyy="3.4649E-05"
        iyz="-8.7464E-07"
        izz="5.6133E-05" />
    </inertial>
    <visual>
      <origin
        xyz="0 0 0"
        rpy="0 0 0" />
      <geometry>
        <mesh
          filename="package://meshes/R3.STL" />
      </geometry>
      <material
        name="">
        <color
          rgba="0.79216 0.81961 0.93333 1" />
      </material>
    </visual>
    <collision>
      <origin
        xyz="0 0 0"
        rpy="0 0 0" />
      <geometry>
        <mesh
          filename="package://meshes/R3.STL" />
      </geometry>
    </collision>
  </link>
  <joint
    name="JR2"
    type="continuous">
    <origin
      xyz="0 -0.0315 0"
      rpy="0 0 0" />
    <parent
      link="R2" />
    <child
      link="R3" />
    <axis
      xyz="0 0 1" />
  </joint>
  <link
    name="R4">
    <inertial>
      <origin
        xyz="-3.71560602003829E-05 -0.109884425270415 0.0645015204124353"
        rpy="0 0 0" />
      <mass
        value="0.0896499629130446" />
      <inertia
        ixx="4.16009895691136E-05"
        ixy="7.61363341609648E-07"
        ixz="-4.44448874012525E-07"
        iyy="3.2411070646171E-05"
        iyz="1.15463620151377E-05"
        izz="4.57659420239507E-05" />
    </inertial>
    <visual>
      <origin
        xyz="0 0 0"
        rpy="0 0 0" />
      <geometry>
        <mesh
          filename="package://meshes/R4.STL" />
      </geometry>
      <material
        name="">
        <color
          rgba="0.792156862745098 0.819607843137255 0.933333333333333 1" />
      </material>
    </visual>
    <collision>
      <origin
        xyz="0 0 0"
        rpy="0 0 0" />
      <geometry>
        <mesh
          filename="package://meshes/R4.STL" />
      </geometry>
    </collision>
  </link>
  <joint
    name="JR3"
    type="continuous">
    <origin
      xyz="0 0 0"
      rpy="0.5236 0 0" />
    <parent
      link="R3" />
    <child
      link="R4" />
    <axis
      xyz="1 0 0" />
  </joint>
  <link
    name="R5">
    <inertial>
      <origin
        xyz="2.35922392732846E-16 -0.0581603167117033 -0.0234974642851387"
        rpy="0 0 0" />
      <mass
        value="0.0272654512429997" />
      <inertia
        ixx="6.43959167351521E-05"
        ixy="2.27606766001115E-20"
        ixz="4.57758707260766E-20"
        iyy="3.91420033245628E-05"
        iyz="-2.60653220840411E-05"
        izz="5.28423727848243E-05" />
    </inertial>
    <visual>
      <origin
        xyz="0 0 0"
        rpy="0 0 0" />
      <geometry>
        <mesh
          filename="package://meshes/R5.STL" />
      </geometry>
      <material
        name="">
        <color
          rgba="0.792156862745098 0.819607843137255 0.933333333333333 1" />
      </material>
    </visual>
    <collision>
      <origin
        xyz="0 0 0"
        rpy="0 0 0" />
      <geometry>
        <mesh
          filename="package://meshes/R5.STL" />
      </geometry>
    </collision>
  </link>
  <joint
    name="JR4"
    type="continuous">
    <origin
      xyz="0 -0.13373 0.078366"
      rpy="-1.0472 0 0" />
    <parent
      link="R4" />
    <child
      link="R5" />
    <axis
      xyz="1 0 0" />
  </joint>
  <link
    name="R6">
    <inertial>
      <origin
        xyz="-1.94903609577537E-05 0.0144662621171153 -0.0218201673886669"
        rpy="0 0 0" />
      <mass
        value="0.15544328108956" />
      <inertia
        ixx="5.58260684034127E-05"
        ixy="8.73883694619815E-07"
        ixz="-1.06078061493619E-20"
        iyy="3.46492828581795E-05"
        iyz="8.90044715309909E-07"
        izz="5.61332220076912E-05" />
    </inertial>
    <visual>
      <origin
        xyz="0 0 0"
        rpy="0 0 0" />
      <geometry>
        <mesh
          filename="package://meshes/R6.STL" />
      </geometry>
      <material
        name="">
        <color
          rgba="0.792156862745098 0.819607843137255 0.933333333333333 1" />
      </material>
    </visual>
    <collision>
      <origin
        xyz="0 0 0"
        rpy="0 0 0" />
      <geometry>
        <mesh
          filename="package://meshes/R6.STL" />
      </geometry>
    </collision>
  </link>
  <joint
    name="JR5"
    type="continuous">
    <origin
      xyz="0 -0.13423 -0.0775"
      rpy="0.5236 0 0" />
    <parent
      link="R5" />
    <child
      link="R6" />
    <axis
      xyz="1 0 0" />
  </joint>
  <link
    name="R7">
    <inertial>
      <origin
        xyz="-0.0103682525758409 -0.0291524556567055 0.00946030945951293"
        rpy="0 0 0" />
      <mass
        value="0.0293701270577348" />
      <inertia
        ixx="5.27259611745445E-05"
        ixy="-2.48306178311266E-16"
        ixz="3.96226789627106E-15"
        iyy="7.6269660952646E-05"
        iyz="-4.07692845377782E-07"
        izz="2.5034690010458E-05" />
    </inertial>
    <visual>
      <origin
        xyz="0 0 0"
        rpy="0 0 0" />
      <geometry>
        <mesh
          filename="package://meshes/R7.STL" />
      </geometry>
      <material
        name="">
        <color
          rgba="0.792156862745098 0.819607843137255 0.933333333333333 1" />
      </material>
    </visual>
    <collision>
      <origin
        xyz="0 0 0"
        rpy="0 0 0" />
      <geometry>
        <mesh
          filename="package://meshes/R7.STL" />
      </geometry>
    </collision>
  </link>
  <joint
    name="JR6"
    type="continuous">
    <origin
      xyz="0 0 0"
      rpy="0 0 0" />
    <parent
      link="R6" />
    <child
      link="R7" />
    <axis
      xyz="0 0 1" />
  </joint>
  <link
    name="L2">
    <inertial>
      <origin
        xyz="5.11962694460522E-12 -0.00793496897620852 0.00493585010633513"
        rpy="0 0 0" />
      <mass
        value="0.00594575048168081" />
      <inertia
        ixx="2.94097568011264E-06"
        ixy="-2.48305668347206E-16"
        ixz="-3.96228856303345E-15"
        iyy="2.92441644469775E-06"
        iyz="-3.827449871227E-08"
        izz="9.84929527953606E-07" />
    </inertial>
    <visual>
      <origin
        xyz="0 0 0"
        rpy="0 0 0" />
      <geometry>
        <mesh
          filename="package://meshes/L2.STL" />
      </geometry>
      <material
        name="">
        <color
          rgba="0.792156862745098 0.819607843137255 0.933333333333333 1" />
      </material>
    </visual>
    <collision>
      <origin
        xyz="0 0 0"
        rpy="0 0 0" />
      <geometry>
        <mesh
          filename="package://meshes/L2.STL" />
      </geometry>
    </collision>
  </link>
  <joint
    name="JL1"
    type="continuous">
    <origin
      xyz="0.049 0.010409 -0.13257"
      rpy="1.5739 0 0" />
    <parent
      link="body" />
    <child
      link="L2" />
    <axis
      xyz="0 1 0" />
  </joint>
  <link
    name="L3">
    <inertial>
      <origin
        xyz="1.9490360957948E-05 -0.0151499843579775 -0.0208201673886668"
        rpy="0 0 0" />
      <mass
        value="0.15544328108956" />
      <inertia
        ixx="5.58260684034127E-05"
        ixy="8.73883694619815E-07"
        ixz="7.37775671905169E-21"
        iyy="3.46492828581794E-05"
        iyz="-8.90044715309545E-07"
        izz="5.61332220076912E-05" />
    </inertial>
    <visual>
      <origin
        xyz="0 0 0"
        rpy="0 0 0" />
      <geometry>
        <mesh
          filename="package://meshes/L3.STL" />
      </geometry>
      <material
        name="">
        <color
          rgba="0.792156862745098 0.819607843137255 0.933333333333333 1" />
      </material>
    </visual>
    <collision>
      <origin
        xyz="0 0 0"
        rpy="0 0 0" />
      <geometry>
        <mesh
          filename="package://meshes/L3.STL" />
      </geometry>
    </collision>
  </link>
  <joint
    name="JL2"
    type="continuous">
    <origin
      xyz="0 -0.0315 0"
      rpy="0 0 0" />
    <parent
      link="L2" />
    <child
      link="L3" />
    <axis
      xyz="0 0 1" />
  </joint>
  <link
    name="L4">
    <inertial>
      <origin
        xyz="3.71560602005702E-05 0.0630194871166001 0.104414323766192"
        rpy="0 0 0" />
      <mass
        value="0.0896499629130445" />
      <inertia
        ixx="4.16009895691135E-05"
        ixy="5.02197314697276E-07"
        ixz="7.24573527441376E-07"
        iyy="4.36739646160413E-05"
        iyz="-1.25252037868802E-05"
        izz="3.45030480540803E-05" />
    </inertial>
    <visual>
      <origin
        xyz="0 0 0"
        rpy="0 0 0" />
      <geometry>
        <mesh
          filename="package://meshes/L4.STL" />
      </geometry>
      <material
        name="">
        <color
          rgba="0.792156862745098 0.819607843137255 0.933333333333333 1" />
      </material>
    </visual>
    <collision>
      <origin
        xyz="0 0 0"
        rpy="0 0 0" />
      <geometry>
        <mesh
          filename="package://meshes/L4.STL" />
      </geometry>
    </collision>
  </link>
  <joint
    name="JL3"
    type="continuous">
    <origin
      xyz="0 -0.0057358 0.0091915"
      rpy="2.1817 0 0" />
    <parent
      link="L3" />
    <child
      link="L4" />
    <axis
      xyz="1 0 0" />
  </joint>
  <link
    name="L5">
    <inertial>
      <origin
        xyz="4.85722573273506E-16 -0.0183390437380094 0.0599869380999931"
        rpy="0 0 0" />
      <mass
        value="0.0272654512429999" />
      <inertia
        ixx="6.43959167351525E-05"
        ixy="6.5837365657827E-20"
        ixz="-1.38536606830353E-19"
        iyy="5.72644987666864E-05"
        iyz="2.44798091780557E-05"
        izz="3.47198773427011E-05" />
    </inertial>
    <visual>
      <origin
        xyz="0 0 0"
        rpy="0 0 0" />
      <geometry>
        <mesh
          filename="package://meshes/L5.STL" />
      </geometry>
      <material
        name="">
        <color
          rgba="0.792156862745098 0.819607843137255 0.933333333333333 1" />
      </material>
    </visual>
    <collision>
      <origin
        xyz="0 0 0"
        rpy="0 0 0" />
      <geometry>
        <mesh
          filename="package://meshes/L5.STL" />
      </geometry>
    </collision>
  </link>
  <joint
    name="JL4"
    type="continuous">
    <origin
      xyz="0 0.078904 0.12697"
      rpy="-1.0472 0 0" />
    <parent
      link="L4" />
    <child
      link="L5" />
    <axis
      xyz="1 0 0" />
  </joint>
  <link
    name="L6">
    <inertial>
      <origin
        xyz="2.33682225148149E-05 -0.0229940897785377 -0.0125097987045415"
        rpy="0 0 0" />
      <mass
        value="0.15544328108956" />
      <inertia
        ixx="5.58260684034126E-05"
        ixy="7.75063095128782E-08"
        ixz="8.85901171526323E-07"
        iyy="5.58181471321927E-05"
        iyz="-2.72667897496436E-06"
        izz="3.49643577336778E-05" />
    </inertial>
    <visual>
      <origin
        xyz="0 0 0"
        rpy="0 0 0" />
      <geometry>
        <mesh
          filename="package://meshes/L6.STL" />
      </geometry>
      <material
        name="">
        <color
          rgba="0.792156862745098 0.819607843137255 0.933333333333333 1" />
      </material>
    </visual>
    <collision>
      <origin
        xyz="0 0 0"
        rpy="0 0 0" />
      <geometry>
        <mesh
          filename="package://meshes/L6.STL" />
      </geometry>
    </collision>
  </link>
  <joint
    name="JL5"
    type="continuous">
    <origin
      xyz="0 -0.065506 0.14048"
      rpy="0.5236 0 0" />
    <parent
      link="L5" />
    <child
      link="L6" />
    <axis
      xyz="1 0 0" />
  </joint>
  <link
    name="L7">
    <inertial>
      <origin
        xyz="0.0103682525737677 0.0119651140515537 0.0282170014639998"
        rpy="0 0 0" />
      <mass
        value="0.0293701270577349" />
      <inertia
        ixx="5.27259611745444E-05"
        ixy="3.96875464577063E-15"
        ixz="-9.79294087641099E-17"
        iyy="2.54946722965885E-05"
        iyz="4.84992874343962E-06"
        izz="7.58096786665151E-05" />
    </inertial>
    <visual>
      <origin
        xyz="0 0 0"
        rpy="0 0 0" />
      <geometry>
        <mesh
          filename="package://meshes/L7.STL" />
      </geometry>
      <material
        name="">
        <color
          rgba="0.792156862745098 0.819607843137255 0.933333333333333 1" />
      </material>
    </visual>
    <collision>
      <origin
        xyz="0 0 0"
        rpy="0 0 0" />
      <geometry>
        <mesh
          filename="package://meshes/L7.STL" />
      </geometry>
    </collision>
  </link>
  <joint
    name="JL6"
    type="continuous">
    <origin
      xyz="0 0 0"
      rpy="0 0 0" />
    <parent
      link="L6" />
    <child
      link="L7" />
    <axis
      xyz="0 0.99619 -0.087156" />
  </joint>
  <link
    name="AR2">
    <inertial>
      <origin
        xyz="-0.0122215328030043 -0.00304504079535874 0.00046755664416805"
        rpy="0 0 0" />
      <mass
        value="0.00782111452958767" />
      <inertia
        ixx="3.46730290731849E-06"
        ixy="-3.56887654541805E-07"
        ixz="5.47990011683571E-08"
        iyy="3.44521472170541E-06"
        iyz="-2.06144819144966E-07"
        izz="2.13431503339268E-06" />
    </inertial>
    <visual>
      <origin
        xyz="0 0 0"
        rpy="0 0 0" />
      <geometry>
        <mesh
          filename="package://meshes/AR2.STL" />
      </geometry>
      <material
        name="">
        <color
          rgba="0.792156862745098 0.819607843137255 0.933333333333333 1" />
      </material>
    </visual>
    <collision>
      <origin
        xyz="0 0 0"
        rpy="0 0 0" />
      <geometry>
        <mesh
          filename="package://meshes/AR2.STL" />
      </geometry>
    </collision>
  </link>
  <joint
    name="JAR1"
    type="continuous">
    <origin
      xyz="-0.0665 0 -0.0001"
      rpy="1.7262 0 0" />
    <parent
      link="body" />
    <child
      link="AR2" />
    <axis
      xyz="1 0 0" />
  </joint>
  <link
    name="AR3">
    <inertial>
      <origin
        xyz="-0.0217424355782832 -0.0598709237463328 0.0138089346841776"
        rpy="0 0 0" />
      <mass
        value="0.097623535640491" />
      <inertia
        ixx="2.66927650742415E-05"
        ixy="-1.51414262049176E-06"
        ixz="-2.59340162798032E-07"
        iyy="2.29946667509428E-05"
        iyz="-4.51570937003064E-07"
        izz="2.16812046230082E-05" />
    </inertial>
    <visual>
      <origin
        xyz="0 0 0"
        rpy="0 0 0" />
      <geometry>
        <mesh
          filename="package://meshes/AR3.STL" />
      </geometry>
      <material
        name="">
        <color
          rgba="0.792156862745098 0.819607843137255 0.933333333333333 1" />
      </material>
    </visual>
    <collision>
      <origin
        xyz="0 0 0"
        rpy="0 0 0" />
      <geometry>
        <mesh
          filename="package://meshes/AR3.STL" />
      </geometry>
    </collision>
  </link>
  <joint
    name="JAR2"
    type="continuous">
    <origin
      xyz="-0.035 -0.019768322112152 0.00303536503079964"
      rpy="0.00863677948697105 0.0507435699806214 0.337108707096089" />
    <parent
      link="AR2" />
    <child
      link="AR3" />
    <axis
      xyz="0 0.151768251539982 0.988416105607601" />
  </joint>
  <link
    name="AR4">
    <inertial>
      <origin
        xyz="-0.0264395498118501 -0.0719680840946816 0.0249388613374165"
        rpy="0 0 0" />
      <mass
        value="0.0261806235165505" />
      <inertia
        ixx="1.29434109350166E-05"
        ixy="-2.0730856844392E-06"
        ixz="1.53907500063378E-06"
        iyy="8.49936634440967E-06"
        iyz="4.30753226979961E-06"
        izz="1.32076307428004E-05" />
    </inertial>
    <visual>
      <origin
        xyz="0 0 0"
        rpy="0 0 0" />
      <geometry>
        <mesh
          filename="package://meshes/AR4.STL" />
      </geometry>
      <material
        name="">
        <color
          rgba="0.792156862745098 0.819607843137255 0.933333333333333 1" />
      </material>
    </visual>
    <collision>
      <origin
        xyz="0 0 0"
        rpy="0 0 0" />
      <geometry>
        <mesh
          filename="package://meshes/AR4.STL" />
      </geometry>
    </collision>
  </link>
  <joint
    name="JAR3"
    type="continuous">
    <origin
      xyz="-0.0391688936407426 -0.105994321647765 0.0375212146577176"
      rpy="-0.401595058674256 0.131487536773221 -0.0485277151924821" />
    <parent
      link="AR3" />
    <child
      link="AR4" />
    <axis
      xyz="0.942500202763317 -0.330334175028508 0.0507217960973566" />
  </joint>
  <link
    name="AL2">
    <inertial>
      <origin
        xyz="0.0122215328030043 -0.00306297937268113 -0.000330212088565167"
        rpy="0 0 0" />
      <mass
        value="0.00782111452958769" />
      <inertia
        ixx="3.46730290731849E-06"
        ixy="3.58990108077455E-07"
        ixz="3.87018190261986E-08"
        iyy="3.46107948276651E-06"
        iyz="1.46447551999455E-07"
        izz="2.11845027233158E-06" />
    </inertial>
    <visual>
      <origin
        xyz="0 0 0"
        rpy="0 0 0" />
      <geometry>
        <mesh
          filename="package://meshes/AL2.STL" />
      </geometry>
      <material
        name="">
        <color
          rgba="0.792156862745098 0.819607843137255 0.933333333333333 1" />
      </material>
    </visual>
    <collision>
      <origin
        xyz="0 0 0"
        rpy="0 0 0" />
      <geometry>
        <mesh
          filename="package://meshes/AL2.STL" />
      </geometry>
    </collision>
  </link>
  <joint
    name="JAL1"
    type="continuous">
    <origin
      xyz="0.0665 0 -0.0001"
      rpy="1.4665 0 0" />
    <parent
      link="body" />
    <child
      link="AL2" />
    <axis
      xyz="1 0 0" />
  </joint>
  <link
    name="AL3">
    <inertial>
      <origin
        xyz="0.00729277157235911 -0.0647229266668686 -0.00238871067636881"
        rpy="0 0 0" />
      <mass
        value="0.097623535640491" />
      <inertia
        ixx="2.71510597381538E-05"
        ixy="5.4954535768441E-07"
        ixz="-2.77333925095466E-07"
        iyy="2.27195249459817E-05"
        iyz="-2.99771975663198E-07"
        izz="2.14980517640569E-05" />
    </inertial>
    <visual>
      <origin
        xyz="0 0 0"
        rpy="0 0 0" />
      <geometry>
        <mesh
          filename="package://meshes/AL3.STL" />
      </geometry>
      <material
        name="">
        <color
          rgba="0.792156862745098 0.819607843137255 0.933333333333333 1" />
      </material>
    </visual>
    <collision>
      <origin
        xyz="0 0 0"
        rpy="0 0 0" />
      <geometry>
        <mesh
          filename="package://meshes/AL3.STL" />
      </geometry>
    </collision>
  </link>
  <joint
    name="JAL2"
    type="continuous">
    <origin
      xyz="0.035 -0.0198847788687522 -0.00214372790736723"
      rpy="-0.000675234731490389 0.0120468245174906 -0.111983173268338" />
    <parent
      link="AL2" />
    <child
      link="AL3" />
    <axis
      xyz="0 0.107186395368361 -0.994238943437611" />
  </joint>
  <link
    name="AL4">
    <inertial>
      <origin
        xyz="0.00913578295485759 -0.0801031112896214 -0.000656322210190963"
        rpy="0 0 0" />
      <mass
        value="0.0261806235165505" />
      <inertia
        ixx="1.36552226908737E-05"
        ixy="8.94157570011036E-07"
        ixz="-2.43003115857642E-07"
        iyy="5.58775082486857E-06"
        iyz="1.98253938483778E-06"
        izz="1.54074345064843E-05" />
    </inertial>
    <visual>
      <origin
        xyz="0 0 0"
        rpy="0 0 0" />
      <geometry>
        <mesh
          filename="package://meshes/AL4.STL" />
      </geometry>
      <material
        name="">
        <color
          rgba="0.792156862745098 0.819607843137255 0.933333333333333 1" />
      </material>
    </visual>
    <collision>
      <origin
        xyz="0 0 0"
        rpy="0 0 0" />
      <geometry>
        <mesh
          filename="package://meshes/AL4.STL" />
      </geometry>
    </collision>
  </link>
  <joint
    name="JAL3"
    type="continuous">
    <origin
      xyz="0.0131719485348661 -0.118037455358604 0.00839636256129469"
      rpy="-0.491746944547984 -0.0544973559727831 0.00759729409276157" />
    <parent
      link="AL3" />
    <child
      link="AL4" />
    <axis
      xyz="0.993664326490195 0.111741162067576 0.0120465331350887" />
  </joint>
  <link
    name="H2">
    <inertial>
      <origin
        xyz="0 0 0"
        rpy="0 0 0" />
      <mass
        value="0" />
      <inertia
        ixx="0"
        ixy="0"
        ixz="0"
        iyy="0"
        iyz="0"
        izz="0" />
    </inertial>
    <visual>
      <origin
        xyz="0 0 0"
        rpy="0 0 0" />
      <geometry>
        <mesh
          filename="package://meshes/H2.STL" />
      </geometry>
      <material
        name="">
        <color
          rgba="1 1 1 1" />
      </material>
    </visual>
    <collision>
      <origin
        xyz="0 0 0"
        rpy="0 0 0" />
      <geometry>
        <mesh
          filename="package://meshes/H2.STL" />
      </geometry>
    </collision>
  </link>
  <joint
    name="JH1"
    type="continuous">
    <origin
      xyz="0 -6.32106971754079E-05 0.0204999025462992"
      rpy="1.57335367827389 0.00172268556231549 -0.592800435653726" />
    <parent
      link="body" />
    <child
      link="H2" />
    <axis
      xyz="0 1 0" />
  </joint>
  <link
    name="H3">
    <inertial>
      <origin
        xyz="0.036913632495691 -0.0261315077775538 0.0562881107039803"
        rpy="0 0 0" />
      <mass
        value="0.070189548920754" />
      <inertia
        ixx="2.26120241044407E-05"
        ixy="-3.16435657178402E-07"
        ixz="1.97667380621252E-05"
        iyy="5.32373444792001E-05"
        iyz="2.57216251711595E-08"
        izz="3.82682129648946E-05" />
    </inertial>
    <visual>
      <origin
        xyz="0 0 0"
        rpy="0 0 0" />
      <geometry>
        <mesh
          filename="package://meshes/H3.STL" />
      </geometry>
      <material
        name="">
        <color
          rgba="0.792156862745098 0.819607843137255 0.933333333333333 1" />
      </material>
    </visual>
    <collision>
      <origin
        xyz="0 0 0"
        rpy="0 0 0" />
      <geometry>
        <mesh
          filename="package://meshes/H3.STL" />
      </geometry>
    </collision>
  </link>
  <joint
    name="JH2"
    type="continuous">
    <origin
      xyz="0 0.01 0"
      rpy="-0.995509566645158 0.333454125428357 0.600667945155879" />
    <parent
      link="H2" />
    <child
      link="H3" />
    <axis
      xyz="0.829378138941034 0 -0.558687661083281" />
  </joint>
</robot>