<?xml version="1.0" ?>
<!-- =================================================================================== -->
<!-- |    This document was autogenerated by xacro from obike.xacro                    | -->
<!-- |    EDITING THIS FILE BY HAND IS NOT RECOMMENDED                                 | -->
<!-- =================================================================================== -->
<robot name="obike">
  <link name="chassic">
    <visual>
      <geometry>
        <mesh filename="/home/fiborobotlab/urdf/robots/obike/meshes/chassic.dae" scale="1 1 1"/>
      </geometry>
    </visual>
  </link>
  <link name="motor_mount">
    <visual>
      <geometry>
        <mesh filename="/home/fiborobotlab/urdf/robots/obike/meshes/motor_mount.dae" scale="1 1 1"/>
      </geometry>
    </visual>
  </link>
  <joint name="motor_mount_joint" type="fixed">
    <origin rpy="0 0 0" xyz="-0.005 0 0.08"/>
    <parent link="chassic"/>
    <child link="motor_mount"/>
  </joint>
  <link name="front_chassic">
    <visual>
      <geometry>
        <mesh filename="/home/fiborobotlab/urdf/robots/obike/meshes/front_chassic.dae" scale="1 1 1"/>
      </geometry>
    </visual>
  </link>
  <joint name="front_chassic_joint" type="fixed">
    <origin rpy="0 0 0" xyz="0.055 0 0.035"/>
    <parent link="chassic"/>
    <child link="front_chassic"/>
  </joint>
  <link name="front_wheel_arm">
    <visual>
      <geometry>
        <mesh filename="/home/fiborobotlab/urdf/robots/obike/meshes/front_wheel_arm.dae" scale="1 1 1"/>
      </geometry>
    </visual>
  </link>
  <joint name="front_wheel_arm_joint" type="continuous">
    <origin rpy="0 2.6179938779914944 0" xyz="0.107304 0 0.03901"/>
    <axis xyz="0 0 1"/>
    <parent link="chassic"/>
    <child link="front_wheel_arm"/>
  </joint>
  <link name="front_wheel">
    <visual>
      <geometry>
        <mesh filename="/home/fiborobotlab/urdf/robots/obike/meshes/front_wheel.dae" scale="1 1 1"/>
      </geometry>
    </visual>
  </link>
  <joint name="front_wheel_joint" type="continuous">
    <origin rpy="-1.5707963267948966 0 0" xyz="0 0 0.035"/>
    <axis xyz="0 0 1"/>
    <parent link="front_wheel_arm"/>
    <child link="front_wheel"/>
  </joint>
  <link name="faulhaber">
    <visual>
      <geometry>
        <mesh filename="/home/fiborobotlab/urdf/robots/obike/meshes/faulhaber.dae" scale="1 1 1"/>
      </geometry>
    </visual>
  </link>
  <joint name="faulhaber_joint" type="fixed">
    <origin rpy="0 1.5707963267948966 0" xyz="0 0 0"/>
    <parent link="motor_mount"/>
    <child link="faulhaber"/>
  </joint>
  <link name="reaction_wheel">
    <visual>
      <geometry>
        <mesh filename="/home/fiborobotlab/urdf/robots/obike/meshes/reaction_wheel.dae" scale="1 1 1"/>
      </geometry>
    </visual>
  </link>
  <joint name="reaction_wheel_joint" type="continuous">
    <origin rpy="0 1.5707963267948966 0" xyz="0.044 0 0"/>
    <axis xyz="0 0 1"/>
    <parent link="motor_mount"/>
    <child link="reaction_wheel"/>
  </joint>
  <link name="reaction_wheel_steel">
    <visual>
      <geometry>
        <mesh filename="/home/fiborobotlab/urdf/robots/obike/meshes/reaction_wheel_steel.dae" scale="1 1 1"/>
      </geometry>
    </visual>
  </link>
  <joint name="reaction_wheel_steel_joint" type="fixed">
    <origin rpy="0 0 0" xyz="0 0 0.004"/>
    <parent link="reaction_wheel"/>
    <child link="reaction_wheel_steel"/>
  </joint>
  <link name="rear_wheel">
    <visual>
      <geometry>
        <mesh filename="/home/fiborobotlab/urdf/robots/obike/meshes/rear_wheel.dae" scale="1 1 1"/>
      </geometry>
    </visual>
  </link>
  <joint name="rear_wheel_joint" type="continuous">
    <origin rpy="1.5707963267948966 0 0" xyz="-0.05 0 0.022"/>
    <axis xyz="0 0 1"/>
    <parent link="chassic"/>
    <child link="rear_wheel"/>
  </joint>
</robot>
