<?xml version="1.0" ?>
<!-- =================================================================================== -->
<!-- |    This document was autogenerated by xacro from obike.xacro                    | -->
<!-- |    EDITING THIS FILE BY HAND IS NOT RECOMMENDED                                 | -->
<!-- =================================================================================== -->
<robot name="obike">
  <link name="base">
		
	</link>
  <link name="body">
    <visual>
      <origin rpy="0 0 0" xyz="0 0 0"/>
      <geometry>
        <box size="0.150 0.04 0.06" xyz="0 0 0"/>
      </geometry>
    </visual>
    <inertial>
      <origin rpy="0 0 0" xyz="0 0 0"/>
      <mass value="0.1850004"/>
      <inertia ixx="8.016684e-05" ixy="0" ixz="0" iyy="0.00040237587" iyz="0" izz="0.00037154247"/>
    </inertial>
  </link>
  <joint name="base_joint" type="continuous">
    <origin rpy="0 0 0" xyz="0 0 0.0665"/>
    <axis xyz="1 0 0"/>
    <parent link="base"/>
    <child link="body"/>
  </joint>
  <link name="reaction_wheel_assembly">
    <visual>
      <origin rpy="0 0 0"/>
      <geometry>
        <cylinder length="0.08" radius="0.0125" rpy="0 0 0" xyz="0 0 0"/>
      </geometry>
    </visual>
    <inertial>
      <origin rpy="0 0 0" xyz="0 0 0"/>
      <mass value="0.212999981913388"/>
      <inertia ixx="0.00012192030214729867" ixy="0" ixz="0" iyy="0.00012192030214729867" iyz="0" izz="1.6640623586983442e-05"/>
    </inertial>
  </link>
  <joint name="reaction_wheel_assembly_joint" type="fixed">
    <origin rpy="0 1.5707963267948966 0" xyz="0 0 0.0605"/>
    <parent link="body"/>
    <child link="reaction_wheel_assembly"/>
  </joint>
  <link name="reaction_wheel">
    <visual>
      <origin rpy="0 0 0"/>
      <geometry>
        <cylinder length="0.01" radius="0.035" rpy="0 0 0" xyz="0 0 0"/>
      </geometry>
    </visual>
    <inertial>
      <origin rpy="0 0 0" xyz="0 0 0"/>
      <mass value="0.19800011006761326"/>
      <inertia ixx="6.228753462543666e-05" ixy="0" ixz="0" iyy="6.228753462543666e-05" iyz="0" izz="0.00012127506741641313"/>
    </inertial>
  </link>
  <joint name="reaction_wheel_joint" type="continuous">
    <origin rpy="0 0 0" xyz="0 0 0.05"/>
    <axis xyz="0 0 1"/>
    <parent link="reaction_wheel_assembly"/>
    <child link="reaction_wheel"/>
  </joint>
  <link name="wheel_0">
    <visual>
      <geometry>
        <cylinder length="0.001" radius="0.0365" rpy="0 0 0" xyz="0 0 0"/>
      </geometry>
    </visual>
    <collision>
      <origin rpy="0 0 0" xyz="0 0 0"/>
      <geometry>
        <cylinder length="0.001" radius="0.0365"/>
      </geometry>
    </collision>
    <inertial>
      <origin rpy="0 0 0" xyz="0 0 0"/>
      <mass value="0.004185386812745002"/>
      <inertia ixx="1.3943441775542774e-06" ixy="0" ixz="0" iyy="1.3943441775542774e-06" iyz="0" izz="2.787990790639764e-06"/>
    </inertial>
  </link>
  <joint name="wheel_0_joint" type="continuous">
    <origin rpy="1.5707963267948966 0 0" xyz="-0.05 0 -0.0365"/>
    <axis xyz="0 0 1"/>
    <parent link="body"/>
    <child link="wheel_0"/>
  </joint>
  <link name="wheel_1">
    <visual>
      <geometry>
        <cylinder length="0.001" radius="0.0365" rpy="0 0 0" xyz="0 0 0"/>
      </geometry>
    </visual>
    <collision>
      <origin rpy="0 0 0" xyz="0 0 0"/>
      <geometry>
        <cylinder length="0.001" radius="0.0365"/>
      </geometry>
    </collision>
    <inertial>
      <origin rpy="0 0 0" xyz="0 0 0"/>
      <mass value="0.004185386812745002"/>
      <inertia ixx="1.3943441775542774e-06" ixy="0" ixz="0" iyy="1.3943441775542774e-06" iyz="0" izz="2.787990790639764e-06"/>
    </inertial>
  </link>
  <joint name="wheel_1_joint" type="continuous">
    <origin rpy="1.5707963267948966 0 0" xyz="0.05 0 -0.0365"/>
    <axis xyz="0 0 1"/>
    <parent link="body"/>
    <child link="wheel_1"/>
  </joint>
</robot>
