<?xml version="1.0" ?>
<!-- =================================================================================== -->
<!-- |    This document was autogenerated by xacro from mooncake.xacro                 | -->
<!-- |    EDITING THIS FILE BY HAND IS NOT RECOMMENDED                                 | -->
<!-- =================================================================================== -->
<robot name="mooncake">
  <!--Lower plate-->
  <link name="base_plate">
    <visual>
      <origin rpy="0 0 0"/>
      <geometry>
        <mesh filename="package://meshes/lower_plate.dae" scale="1 1 1"/>
      </geometry>
    </visual>
    <collision>
      <origin rpy="0 0 0" xyz="0 0 0"/>
      <geometry>
        <cylinder length="0.006" radius="0.15"/>
      </geometry>
    </collision>
    <inertial>
      <origin rpy="0 0 0" xyz="0 0 0"/>
      <mass value="0.5140273899803619"/>
      <inertia ixx="0.0028929461508094764" ixy="0" ixz="0" iyy="0.0028929461508094764" iyz="0" izz="0.005782808137279071"/>
    </inertial>
    <!-- <xacro:collision_cylinder length="0.1745" radius="0.15" xyz="0 0 0.08425"/> -->
  </link>
  <!--Upper plate-->
  <link name="upper_plate">
    <visual>
      <geometry>
        <mesh filename="package://meshes/upper_plate.dae" scale="1 1 1"/>
      </geometry>
    </visual>
    <collision>
      <origin rpy="0 0 0" xyz="0 0 0"/>
      <geometry>
        <cylinder length="0.006" radius="0.15"/>
      </geometry>
    </collision>
    <inertial>
      <origin rpy="0 0 0" xyz="0 0 0"/>
      <mass value="0.5140273899803619"/>
      <inertia ixx="0.0028929461508094764" ixy="0" ixz="0" iyy="0.0028929461508094764" iyz="0" izz="0.005782808137279071"/>
    </inertial>
  </link>
  <joint name="upper_plate_joint" type="fixed">
    <origin rpy="0 0 0" xyz="0 0 0.1685"/>
    <parent link="base_plate"/>
    <child link="upper_plate"/>
  </joint>
  <link name="pillar_0">
    <visual>
      <geometry>
        <mesh filename="package://meshes/pillar.dae" scale="1 1 1"/>
      </geometry>
    </visual>
    <collision>
      <origin rpy="0 0 0" xyz="0 0 0"/>
      <geometry>
        <box size="0.0225 0.006 0.174"/>
      </geometry>
    </collision>
    <inertial>
      <origin rpy="0 0 0" xyz="0 0 0"/>
      <mass value="0.028469879999999996"/>
      <inertia ixx="7.191491687999999e-05" ixy="0" ixz="0" iyy="7.303058030249998e-05" iyz="0" izz="1.2864827024999998e-06"/>
    </inertial>
  </link>
  <joint name="pillar_0_joint" type="fixed">
    <origin rpy="0 0 0.0" xyz="0.13125 0.022 0.08425"/>
    <parent link="base_plate"/>
    <child link="pillar_0"/>
  </joint>
  <link name="pillar_1">
    <visual>
      <geometry>
        <mesh filename="package://meshes/pillar.dae" scale="1 1 1"/>
      </geometry>
    </visual>
    <collision>
      <origin rpy="0 0 0" xyz="0 0 0"/>
      <geometry>
        <box size="0.0225 0.006 0.174"/>
      </geometry>
    </collision>
    <inertial>
      <origin rpy="0 0 0" xyz="0 0 0"/>
      <mass value="0.028469879999999996"/>
      <inertia ixx="7.191491687999999e-05" ixy="0" ixz="0" iyy="7.303058030249998e-05" iyz="0" izz="1.2864827024999998e-06"/>
    </inertial>
  </link>
  <joint name="pillar_1_joint" type="fixed">
    <origin rpy="0 0 0.0" xyz="0.13125 -0.022 0.08425"/>
    <parent link="base_plate"/>
    <child link="pillar_1"/>
  </joint>
  <link name="pillar_2">
    <visual>
      <geometry>
        <mesh filename="package://meshes/pillar.dae" scale="1 1 1"/>
      </geometry>
    </visual>
    <collision>
      <origin rpy="0 0 0" xyz="0 0 0"/>
      <geometry>
        <box size="0.0225 0.006 0.174"/>
      </geometry>
    </collision>
    <inertial>
      <origin rpy="0 0 0" xyz="0 0 0"/>
      <mass value="0.028469879999999996"/>
      <inertia ixx="7.191491687999999e-05" ixy="0" ixz="0" iyy="7.303058030249998e-05" iyz="0" izz="1.2864827024999998e-06"/>
    </inertial>
  </link>
  <joint name="pillar_2_joint" type="fixed">
    <origin rpy="0 0 1.0471975511965976" xyz="0.04657244111674237 0.12466583424670757 0.08425"/>
    <parent link="base_plate"/>
    <child link="pillar_2"/>
  </joint>
  <link name="pillar_3">
    <visual>
      <geometry>
        <mesh filename="package://meshes/pillar.dae" scale="1 1 1"/>
      </geometry>
    </visual>
    <collision>
      <origin rpy="0 0 0" xyz="0 0 0"/>
      <geometry>
        <box size="0.0225 0.006 0.174"/>
      </geometry>
    </collision>
    <inertial>
      <origin rpy="0 0 0" xyz="0 0 0"/>
      <mass value="0.028469879999999996"/>
      <inertia ixx="7.191491687999999e-05" ixy="0" ixz="0" iyy="7.303058030249998e-05" iyz="0" izz="1.2864827024999998e-06"/>
    </inertial>
  </link>
  <joint name="pillar_3_joint" type="fixed">
    <origin rpy="0 0 1.0471975511965976" xyz="0.08467755888325766 0.10266583424670757 0.08425"/>
    <parent link="base_plate"/>
    <child link="pillar_3"/>
  </joint>
  <link name="pillar_4">
    <visual>
      <geometry>
        <mesh filename="package://meshes/pillar.dae" scale="1 1 1"/>
      </geometry>
    </visual>
    <collision>
      <origin rpy="0 0 0" xyz="0 0 0"/>
      <geometry>
        <box size="0.0225 0.006 0.174"/>
      </geometry>
    </collision>
    <inertial>
      <origin rpy="0 0 0" xyz="0 0 0"/>
      <mass value="0.028469879999999996"/>
      <inertia ixx="7.191491687999999e-05" ixy="0" ixz="0" iyy="7.303058030249998e-05" iyz="0" izz="1.2864827024999998e-06"/>
    </inertial>
  </link>
  <joint name="pillar_4_joint" type="fixed">
    <origin rpy="0 0 2.0943951023931953" xyz="-0.08467755888325762 0.10266583424670758 0.08425"/>
    <parent link="base_plate"/>
    <child link="pillar_4"/>
  </joint>
  <link name="pillar_5">
    <visual>
      <geometry>
        <mesh filename="package://meshes/pillar.dae" scale="1 1 1"/>
      </geometry>
    </visual>
    <collision>
      <origin rpy="0 0 0" xyz="0 0 0"/>
      <geometry>
        <box size="0.0225 0.006 0.174"/>
      </geometry>
    </collision>
    <inertial>
      <origin rpy="0 0 0" xyz="0 0 0"/>
      <mass value="0.028469879999999996"/>
      <inertia ixx="7.191491687999999e-05" ixy="0" ixz="0" iyy="7.303058030249998e-05" iyz="0" izz="1.2864827024999998e-06"/>
    </inertial>
  </link>
  <joint name="pillar_5_joint" type="fixed">
    <origin rpy="0 0 2.0943951023931953" xyz="-0.04657244111674232 0.12466583424670757 0.08425"/>
    <parent link="base_plate"/>
    <child link="pillar_5"/>
  </joint>
  <link name="pillar_6">
    <visual>
      <geometry>
        <mesh filename="package://meshes/pillar.dae" scale="1 1 1"/>
      </geometry>
    </visual>
    <collision>
      <origin rpy="0 0 0" xyz="0 0 0"/>
      <geometry>
        <box size="0.0225 0.006 0.174"/>
      </geometry>
    </collision>
    <inertial>
      <origin rpy="0 0 0" xyz="0 0 0"/>
      <mass value="0.028469879999999996"/>
      <inertia ixx="7.191491687999999e-05" ixy="0" ixz="0" iyy="7.303058030249998e-05" iyz="0" izz="1.2864827024999998e-06"/>
    </inertial>
  </link>
  <joint name="pillar_6_joint" type="fixed">
    <origin rpy="0 0 3.141592653589793" xyz="-0.13125 -0.02199999999999998 0.08425"/>
    <parent link="base_plate"/>
    <child link="pillar_6"/>
  </joint>
  <link name="pillar_7">
    <visual>
      <geometry>
        <mesh filename="package://meshes/pillar.dae" scale="1 1 1"/>
      </geometry>
    </visual>
    <collision>
      <origin rpy="0 0 0" xyz="0 0 0"/>
      <geometry>
        <box size="0.0225 0.006 0.174"/>
      </geometry>
    </collision>
    <inertial>
      <origin rpy="0 0 0" xyz="0 0 0"/>
      <mass value="0.028469879999999996"/>
      <inertia ixx="7.191491687999999e-05" ixy="0" ixz="0" iyy="7.303058030249998e-05" iyz="0" izz="1.2864827024999998e-06"/>
    </inertial>
  </link>
  <joint name="pillar_7_joint" type="fixed">
    <origin rpy="0 0 3.141592653589793" xyz="-0.13125 0.022000000000000016 0.08425"/>
    <parent link="base_plate"/>
    <child link="pillar_7"/>
  </joint>
  <link name="pillar_8">
    <visual>
      <geometry>
        <mesh filename="package://meshes/pillar.dae" scale="1 1 1"/>
      </geometry>
    </visual>
    <collision>
      <origin rpy="0 0 0" xyz="0 0 0"/>
      <geometry>
        <box size="0.0225 0.006 0.174"/>
      </geometry>
    </collision>
    <inertial>
      <origin rpy="0 0 0" xyz="0 0 0"/>
      <mass value="0.028469879999999996"/>
      <inertia ixx="7.191491687999999e-05" ixy="0" ixz="0" iyy="7.303058030249998e-05" iyz="0" izz="1.2864827024999998e-06"/>
    </inertial>
  </link>
  <joint name="pillar_8_joint" type="fixed">
    <origin rpy="0 0 4.1887902047863905" xyz="-0.046572441116742413 -0.12466583424670755 0.08425"/>
    <parent link="base_plate"/>
    <child link="pillar_8"/>
  </joint>
  <link name="pillar_9">
    <visual>
      <geometry>
        <mesh filename="package://meshes/pillar.dae" scale="1 1 1"/>
      </geometry>
    </visual>
    <collision>
      <origin rpy="0 0 0" xyz="0 0 0"/>
      <geometry>
        <box size="0.0225 0.006 0.174"/>
      </geometry>
    </collision>
    <inertial>
      <origin rpy="0 0 0" xyz="0 0 0"/>
      <mass value="0.028469879999999996"/>
      <inertia ixx="7.191491687999999e-05" ixy="0" ixz="0" iyy="7.303058030249998e-05" iyz="0" izz="1.2864827024999998e-06"/>
    </inertial>
  </link>
  <joint name="pillar_9_joint" type="fixed">
    <origin rpy="0 0 4.1887902047863905" xyz="-0.0846775588832577 -0.10266583424670753 0.08425"/>
    <parent link="base_plate"/>
    <child link="pillar_9"/>
  </joint>
  <link name="pillar_10">
    <visual>
      <geometry>
        <mesh filename="package://meshes/pillar.dae" scale="1 1 1"/>
      </geometry>
    </visual>
    <collision>
      <origin rpy="0 0 0" xyz="0 0 0"/>
      <geometry>
        <box size="0.0225 0.006 0.174"/>
      </geometry>
    </collision>
    <inertial>
      <origin rpy="0 0 0" xyz="0 0 0"/>
      <mass value="0.028469879999999996"/>
      <inertia ixx="7.191491687999999e-05" ixy="0" ixz="0" iyy="7.303058030249998e-05" iyz="0" izz="1.2864827024999998e-06"/>
    </inertial>
  </link>
  <joint name="pillar_10_joint" type="fixed">
    <origin rpy="0 0 5.235987755982988" xyz="0.08467755888325758 -0.10266583424670765 0.08425"/>
    <parent link="base_plate"/>
    <child link="pillar_10"/>
  </joint>
  <link name="pillar_11">
    <visual>
      <geometry>
        <mesh filename="package://meshes/pillar.dae" scale="1 1 1"/>
      </geometry>
    </visual>
    <collision>
      <origin rpy="0 0 0" xyz="0 0 0"/>
      <geometry>
        <box size="0.0225 0.006 0.174"/>
      </geometry>
    </collision>
    <inertial>
      <origin rpy="0 0 0" xyz="0 0 0"/>
      <mass value="0.028469879999999996"/>
      <inertia ixx="7.191491687999999e-05" ixy="0" ixz="0" iyy="7.303058030249998e-05" iyz="0" izz="1.2864827024999998e-06"/>
    </inertial>
  </link>
  <joint name="pillar_11_joint" type="fixed">
    <origin rpy="0 0 5.235987755982988" xyz="0.04657244111674226 -0.12466583424670762 0.08425"/>
    <parent link="base_plate"/>
    <child link="pillar_11"/>
  </joint>
  <link name="motor_mount_0">
    <visual>
      <geometry>
        <mesh filename="package://meshes/motor_mount.dae" scale="1 1 1"/>
      </geometry>
    </visual>
  </link>
  <joint name="motor_mount_0_joint" type="fixed">
    <origin rpy="0 0 -3.141592653589793" xyz="-0.095 -1.1634144591899856e-17 0"/>
    <parent link="base_plate"/>
    <child link="motor_mount_0"/>
  </joint>
  <link name="motor_0">
    <visual>
      <geometry>
        <mesh filename="package://meshes/ZGX38REE.dae" scale="1 1 1"/>
      </geometry>
    </visual>
    <collision>
      <origin rpy="0 0 0" xyz="0 0 0"/>
      <geometry>
        <cylinder length="0.11" radius="0.019"/>
      </geometry>
    </collision>
    <inertial>
      <origin rpy="0 0 0" xyz="0 0 0"/>
      <mass value="0.6144067730496996"/>
      <inertia ixx="0.0006749770407595159" ixy="0" ixz="0" iyy="0.0006749770407595159" iyz="0" izz="0.00011090042253547078"/>
    </inertial>
  </link>
  <joint name="motor_0_joint" type="fixed">
    <origin rpy="0 -0.6981317007977318 0" xyz="-0.033202134613707274 0 -0.003797792545214791"/>
    <parent link="motor_mount_0"/>
    <child link="motor_0"/>
  </joint>
  <link name="wheel_0">
    <visual>
      <geometry>
        <mesh filename="package://meshes/omni_wheel.dae" scale="1 1 1"/>
      </geometry>
    </visual>
    <inertial>
      <origin rpy="0 0 0" xyz="0 0 0"/>
      <mass value="0.30139914330089534"/>
      <inertia ixx="0.00020914934489905617" ixy="0" ixz="0" iyy="0.00020914934489905617" iyz="0" izz="0.00037674892912611924"/>
    </inertial>
  </link>
  <joint name="wheel_0_joint" type="continuous">
    <origin rpy="0 0 0" xyz="0 0 -0.10666"/>
    <axis xyz="0 0 -1"/>
    <parent link="motor_0"/>
    <child link="wheel_0"/>
  </joint>
  <link name="roller_0_0_0">
    <collision>
      <origin rpy="0 0 0" xyz="0 0 0"/>
      <geometry>
        <sphere radius="0.0095"/>
      </geometry>
    </collision>
    <inertial>
      <origin rpy="0 0 0" xyz="0 0 0"/>
      <mass value="0.0035913640018287317"/>
      <inertia ixx="1.2964824046601722e-07" ixy="0" ixz="0" iyy="1.2964824046601722e-07" iyz="0" izz="1.2964824046601722e-07"/>
    </inertial>
  </link>
  <joint name="roller_0_0_0_joint" type="continuous">
    <origin rpy="0 0 -0.0" xyz="0.0 0.042 -0.01438"/>
    <axis xyz="1 0 0"/>
    <parent link="wheel_0"/>
    <child link="roller_0_0_0"/>
  </joint>
  <link name="roller_0_0_1">
    <collision>
      <origin rpy="0 0 0" xyz="0 0 0"/>
      <geometry>
        <sphere radius="0.0095"/>
      </geometry>
    </collision>
    <inertial>
      <origin rpy="0 0 0" xyz="0 0 0"/>
      <mass value="0.0035913640018287317"/>
      <inertia ixx="1.2964824046601722e-07" ixy="0" ixz="0" iyy="1.2964824046601722e-07" iyz="0" izz="1.2964824046601722e-07"/>
    </inertial>
  </link>
  <joint name="roller_0_0_1_joint" type="continuous">
    <origin rpy="0 0 -0.6981317007977318" xyz="0.02699707960683465 0.03217386661099708 -0.01438"/>
    <axis xyz="1 0 0"/>
    <parent link="wheel_0"/>
    <child link="roller_0_0_1"/>
  </joint>
  <link name="roller_0_0_2">
    <collision>
      <origin rpy="0 0 0" xyz="0 0 0"/>
      <geometry>
        <sphere radius="0.0095"/>
      </geometry>
    </collision>
    <inertial>
      <origin rpy="0 0 0" xyz="0 0 0"/>
      <mass value="0.0035913640018287317"/>
      <inertia ixx="1.2964824046601722e-07" ixy="0" ixz="0" iyy="1.2964824046601722e-07" iyz="0" izz="1.2964824046601722e-07"/>
    </inertial>
  </link>
  <joint name="roller_0_0_2_joint" type="continuous">
    <origin rpy="0 0 -1.3962634015954636" xyz="0.04136192562651274 0.0072932234620110776 -0.01438"/>
    <axis xyz="1 0 0"/>
    <parent link="wheel_0"/>
    <child link="roller_0_0_2"/>
  </joint>
  <link name="roller_0_0_3">
    <collision>
      <origin rpy="0 0 0" xyz="0 0 0"/>
      <geometry>
        <sphere radius="0.0095"/>
      </geometry>
    </collision>
    <inertial>
      <origin rpy="0 0 0" xyz="0 0 0"/>
      <mass value="0.0035913640018287317"/>
      <inertia ixx="1.2964824046601722e-07" ixy="0" ixz="0" iyy="1.2964824046601722e-07" iyz="0" izz="1.2964824046601722e-07"/>
    </inertial>
  </link>
  <joint name="roller_0_0_3_joint" type="continuous">
    <origin rpy="0 0 -2.0943951023931953" xyz="0.036373066958946425 -0.02099999999999999 -0.01438"/>
    <axis xyz="1 0 0"/>
    <parent link="wheel_0"/>
    <child link="roller_0_0_3"/>
  </joint>
  <link name="roller_0_0_4">
    <collision>
      <origin rpy="0 0 0" xyz="0 0 0"/>
      <geometry>
        <sphere radius="0.0095"/>
      </geometry>
    </collision>
    <inertial>
      <origin rpy="0 0 0" xyz="0 0 0"/>
      <mass value="0.0035913640018287317"/>
      <inertia ixx="1.2964824046601722e-07" ixy="0" ixz="0" iyy="1.2964824046601722e-07" iyz="0" izz="1.2964824046601722e-07"/>
    </inertial>
  </link>
  <joint name="roller_0_0_4_joint" type="continuous">
    <origin rpy="0 0 -2.792526803190927" xyz="0.014364846019678093 -0.03946709007300815 -0.01438"/>
    <axis xyz="1 0 0"/>
    <parent link="wheel_0"/>
    <child link="roller_0_0_4"/>
  </joint>
  <link name="roller_0_0_5">
    <collision>
      <origin rpy="0 0 0" xyz="0 0 0"/>
      <geometry>
        <sphere radius="0.0095"/>
      </geometry>
    </collision>
    <inertial>
      <origin rpy="0 0 0" xyz="0 0 0"/>
      <mass value="0.0035913640018287317"/>
      <inertia ixx="1.2964824046601722e-07" ixy="0" ixz="0" iyy="1.2964824046601722e-07" iyz="0" izz="1.2964824046601722e-07"/>
    </inertial>
  </link>
  <joint name="roller_0_0_5_joint" type="continuous">
    <origin rpy="0 0 -3.490658503988659" xyz="-0.014364846019678084 -0.03946709007300816 -0.01438"/>
    <axis xyz="1 0 0"/>
    <parent link="wheel_0"/>
    <child link="roller_0_0_5"/>
  </joint>
  <link name="roller_0_0_6">
    <collision>
      <origin rpy="0 0 0" xyz="0 0 0"/>
      <geometry>
        <sphere radius="0.0095"/>
      </geometry>
    </collision>
    <inertial>
      <origin rpy="0 0 0" xyz="0 0 0"/>
      <mass value="0.0035913640018287317"/>
      <inertia ixx="1.2964824046601722e-07" ixy="0" ixz="0" iyy="1.2964824046601722e-07" iyz="0" izz="1.2964824046601722e-07"/>
    </inertial>
  </link>
  <joint name="roller_0_0_6_joint" type="continuous">
    <origin rpy="0 0 -4.1887902047863905" xyz="-0.03637306695894641 -0.02100000000000002 -0.01438"/>
    <axis xyz="1 0 0"/>
    <parent link="wheel_0"/>
    <child link="roller_0_0_6"/>
  </joint>
  <link name="roller_0_0_7">
    <collision>
      <origin rpy="0 0 0" xyz="0 0 0"/>
      <geometry>
        <sphere radius="0.0095"/>
      </geometry>
    </collision>
    <inertial>
      <origin rpy="0 0 0" xyz="0 0 0"/>
      <mass value="0.0035913640018287317"/>
      <inertia ixx="1.2964824046601722e-07" ixy="0" ixz="0" iyy="1.2964824046601722e-07" iyz="0" izz="1.2964824046601722e-07"/>
    </inertial>
  </link>
  <joint name="roller_0_0_7_joint" type="continuous">
    <origin rpy="0 0 -4.886921905584122" xyz="-0.041361925626512745 0.007293223462011059 -0.01438"/>
    <axis xyz="1 0 0"/>
    <parent link="wheel_0"/>
    <child link="roller_0_0_7"/>
  </joint>
  <link name="roller_0_0_8">
    <collision>
      <origin rpy="0 0 0" xyz="0 0 0"/>
      <geometry>
        <sphere radius="0.0095"/>
      </geometry>
    </collision>
    <inertial>
      <origin rpy="0 0 0" xyz="0 0 0"/>
      <mass value="0.0035913640018287317"/>
      <inertia ixx="1.2964824046601722e-07" ixy="0" ixz="0" iyy="1.2964824046601722e-07" iyz="0" izz="1.2964824046601722e-07"/>
    </inertial>
  </link>
  <joint name="roller_0_0_8_joint" type="continuous">
    <origin rpy="0 0 -5.585053606381854" xyz="-0.026997079606834663 0.03217386661099707 -0.01438"/>
    <axis xyz="1 0 0"/>
    <parent link="wheel_0"/>
    <child link="roller_0_0_8"/>
  </joint>
  <link name="roller_0_1_0">
    <collision>
      <origin rpy="0 0 0" xyz="0 0 0"/>
      <geometry>
        <sphere radius="0.0095"/>
      </geometry>
    </collision>
    <inertial>
      <origin rpy="0 0 0" xyz="0 0 0"/>
      <mass value="0.0035913640018287317"/>
      <inertia ixx="1.2964824046601722e-07" ixy="0" ixz="0" iyy="1.2964824046601722e-07" iyz="0" izz="1.2964824046601722e-07"/>
    </inertial>
  </link>
  <joint name="roller_0_1_0_joint" type="continuous">
    <origin rpy="0 0 -0.3490658503988659" xyz="0.014364846019678086 0.03946709007300816 0.01438"/>
    <axis xyz="1 0 0"/>
    <parent link="wheel_0"/>
    <child link="roller_0_1_0"/>
  </joint>
  <link name="roller_0_1_1">
    <collision>
      <origin rpy="0 0 0" xyz="0 0 0"/>
      <geometry>
        <sphere radius="0.0095"/>
      </geometry>
    </collision>
    <inertial>
      <origin rpy="0 0 0" xyz="0 0 0"/>
      <mass value="0.0035913640018287317"/>
      <inertia ixx="1.2964824046601722e-07" ixy="0" ixz="0" iyy="1.2964824046601722e-07" iyz="0" izz="1.2964824046601722e-07"/>
    </inertial>
  </link>
  <joint name="roller_0_1_1_joint" type="continuous">
    <origin rpy="0 0 -1.0471975511965976" xyz="0.036373066958946425 0.021000000000000005 0.01438"/>
    <axis xyz="1 0 0"/>
    <parent link="wheel_0"/>
    <child link="roller_0_1_1"/>
  </joint>
  <link name="roller_0_1_2">
    <collision>
      <origin rpy="0 0 0" xyz="0 0 0"/>
      <geometry>
        <sphere radius="0.0095"/>
      </geometry>
    </collision>
    <inertial>
      <origin rpy="0 0 0" xyz="0 0 0"/>
      <mass value="0.0035913640018287317"/>
      <inertia ixx="1.2964824046601722e-07" ixy="0" ixz="0" iyy="1.2964824046601722e-07" iyz="0" izz="1.2964824046601722e-07"/>
    </inertial>
  </link>
  <joint name="roller_0_1_2_joint" type="continuous">
    <origin rpy="0 0 -1.7453292519943295" xyz="0.04136192562651274 -0.007293223462011073 0.01438"/>
    <axis xyz="1 0 0"/>
    <parent link="wheel_0"/>
    <child link="roller_0_1_2"/>
  </joint>
  <link name="roller_0_1_3">
    <collision>
      <origin rpy="0 0 0" xyz="0 0 0"/>
      <geometry>
        <sphere radius="0.0095"/>
      </geometry>
    </collision>
    <inertial>
      <origin rpy="0 0 0" xyz="0 0 0"/>
      <mass value="0.0035913640018287317"/>
      <inertia ixx="1.2964824046601722e-07" ixy="0" ixz="0" iyy="1.2964824046601722e-07" iyz="0" izz="1.2964824046601722e-07"/>
    </inertial>
  </link>
  <joint name="roller_0_1_3_joint" type="continuous">
    <origin rpy="0 0 -2.443460952792061" xyz="0.02699707960683466 -0.032173866610997075 0.01438"/>
    <axis xyz="1 0 0"/>
    <parent link="wheel_0"/>
    <child link="roller_0_1_3"/>
  </joint>
  <link name="roller_0_1_4">
    <collision>
      <origin rpy="0 0 0" xyz="0 0 0"/>
      <geometry>
        <sphere radius="0.0095"/>
      </geometry>
    </collision>
    <inertial>
      <origin rpy="0 0 0" xyz="0 0 0"/>
      <mass value="0.0035913640018287317"/>
      <inertia ixx="1.2964824046601722e-07" ixy="0" ixz="0" iyy="1.2964824046601722e-07" iyz="0" izz="1.2964824046601722e-07"/>
    </inertial>
  </link>
  <joint name="roller_0_1_4_joint" type="continuous">
    <origin rpy="0 0 -3.141592653589793" xyz="5.143516556418884e-18 -0.042 0.01438"/>
    <axis xyz="1 0 0"/>
    <parent link="wheel_0"/>
    <child link="roller_0_1_4"/>
  </joint>
  <link name="roller_0_1_5">
    <collision>
      <origin rpy="0 0 0" xyz="0 0 0"/>
      <geometry>
        <sphere radius="0.0095"/>
      </geometry>
    </collision>
    <inertial>
      <origin rpy="0 0 0" xyz="0 0 0"/>
      <mass value="0.0035913640018287317"/>
      <inertia ixx="1.2964824046601722e-07" ixy="0" ixz="0" iyy="1.2964824046601722e-07" iyz="0" izz="1.2964824046601722e-07"/>
    </inertial>
  </link>
  <joint name="roller_0_1_5_joint" type="continuous">
    <origin rpy="0 0 -3.839724354387525" xyz="-0.02699707960683465 -0.03217386661099708 0.01438"/>
    <axis xyz="1 0 0"/>
    <parent link="wheel_0"/>
    <child link="roller_0_1_5"/>
  </joint>
  <link name="roller_0_1_6">
    <collision>
      <origin rpy="0 0 0" xyz="0 0 0"/>
      <geometry>
        <sphere radius="0.0095"/>
      </geometry>
    </collision>
    <inertial>
      <origin rpy="0 0 0" xyz="0 0 0"/>
      <mass value="0.0035913640018287317"/>
      <inertia ixx="1.2964824046601722e-07" ixy="0" ixz="0" iyy="1.2964824046601722e-07" iyz="0" izz="1.2964824046601722e-07"/>
    </inertial>
  </link>
  <joint name="roller_0_1_6_joint" type="continuous">
    <origin rpy="0 0 -4.537856055185257" xyz="-0.04136192562651274 -0.007293223462011074 0.01438"/>
    <axis xyz="1 0 0"/>
    <parent link="wheel_0"/>
    <child link="roller_0_1_6"/>
  </joint>
  <link name="roller_0_1_7">
    <collision>
      <origin rpy="0 0 0" xyz="0 0 0"/>
      <geometry>
        <sphere radius="0.0095"/>
      </geometry>
    </collision>
    <inertial>
      <origin rpy="0 0 0" xyz="0 0 0"/>
      <mass value="0.0035913640018287317"/>
      <inertia ixx="1.2964824046601722e-07" ixy="0" ixz="0" iyy="1.2964824046601722e-07" iyz="0" izz="1.2964824046601722e-07"/>
    </inertial>
  </link>
  <joint name="roller_0_1_7_joint" type="continuous">
    <origin rpy="0 0 -5.235987755982989" xyz="-0.036373066958946425 0.021000000000000005 0.01438"/>
    <axis xyz="1 0 0"/>
    <parent link="wheel_0"/>
    <child link="roller_0_1_7"/>
  </joint>
  <link name="roller_0_1_8">
    <collision>
      <origin rpy="0 0 0" xyz="0 0 0"/>
      <geometry>
        <sphere radius="0.0095"/>
      </geometry>
    </collision>
    <inertial>
      <origin rpy="0 0 0" xyz="0 0 0"/>
      <mass value="0.0035913640018287317"/>
      <inertia ixx="1.2964824046601722e-07" ixy="0" ixz="0" iyy="1.2964824046601722e-07" iyz="0" izz="1.2964824046601722e-07"/>
    </inertial>
  </link>
  <joint name="roller_0_1_8_joint" type="continuous">
    <origin rpy="0 0 -5.93411945678072" xyz="-0.014364846019678117 0.039467090073008144 0.01438"/>
    <axis xyz="1 0 0"/>
    <parent link="wheel_0"/>
    <child link="roller_0_1_8"/>
  </joint>
  <link name="motor_mount_1">
    <visual>
      <geometry>
        <mesh filename="package://meshes/motor_mount.dae" scale="1 1 1"/>
      </geometry>
    </visual>
  </link>
  <joint name="motor_mount_1_joint" type="fixed">
    <origin rpy="0 0 -1.0471975511965976" xyz="0.047500000000000014 -0.08227241335952167 0"/>
    <parent link="base_plate"/>
    <child link="motor_mount_1"/>
  </joint>
  <link name="motor_1">
    <visual>
      <geometry>
        <mesh filename="package://meshes/ZGX38REE.dae" scale="1 1 1"/>
      </geometry>
    </visual>
    <collision>
      <origin rpy="0 0 0" xyz="0 0 0"/>
      <geometry>
        <cylinder length="0.11" radius="0.019"/>
      </geometry>
    </collision>
    <inertial>
      <origin rpy="0 0 0" xyz="0 0 0"/>
      <mass value="0.6144067730496996"/>
      <inertia ixx="0.0006749770407595159" ixy="0" ixz="0" iyy="0.0006749770407595159" iyz="0" izz="0.00011090042253547078"/>
    </inertial>
  </link>
  <joint name="motor_1_joint" type="fixed">
    <origin rpy="0 -0.6981317007977318 0" xyz="-0.033202134613707274 0 -0.003797792545214791"/>
    <parent link="motor_mount_1"/>
    <child link="motor_1"/>
  </joint>
  <link name="wheel_1">
    <visual>
      <geometry>
        <mesh filename="package://meshes/omni_wheel.dae" scale="1 1 1"/>
      </geometry>
    </visual>
    <inertial>
      <origin rpy="0 0 0" xyz="0 0 0"/>
      <mass value="0.30139914330089534"/>
      <inertia ixx="0.00020914934489905617" ixy="0" ixz="0" iyy="0.00020914934489905617" iyz="0" izz="0.00037674892912611924"/>
    </inertial>
  </link>
  <joint name="wheel_1_joint" type="continuous">
    <origin rpy="0 0 0" xyz="0 0 -0.10666"/>
    <axis xyz="0 0 -1"/>
    <parent link="motor_1"/>
    <child link="wheel_1"/>
  </joint>
  <link name="roller_1_0_0">
    <collision>
      <origin rpy="0 0 0" xyz="0 0 0"/>
      <geometry>
        <sphere radius="0.0095"/>
      </geometry>
    </collision>
    <inertial>
      <origin rpy="0 0 0" xyz="0 0 0"/>
      <mass value="0.0035913640018287317"/>
      <inertia ixx="1.2964824046601722e-07" ixy="0" ixz="0" iyy="1.2964824046601722e-07" iyz="0" izz="1.2964824046601722e-07"/>
    </inertial>
  </link>
  <joint name="roller_1_0_0_joint" type="continuous">
    <origin rpy="0 0 -0.0" xyz="0.0 0.042 -0.01438"/>
    <axis xyz="1 0 0"/>
    <parent link="wheel_1"/>
    <child link="roller_1_0_0"/>
  </joint>
  <link name="roller_1_0_1">
    <collision>
      <origin rpy="0 0 0" xyz="0 0 0"/>
      <geometry>
        <sphere radius="0.0095"/>
      </geometry>
    </collision>
    <inertial>
      <origin rpy="0 0 0" xyz="0 0 0"/>
      <mass value="0.0035913640018287317"/>
      <inertia ixx="1.2964824046601722e-07" ixy="0" ixz="0" iyy="1.2964824046601722e-07" iyz="0" izz="1.2964824046601722e-07"/>
    </inertial>
  </link>
  <joint name="roller_1_0_1_joint" type="continuous">
    <origin rpy="0 0 -0.6981317007977318" xyz="0.02699707960683465 0.03217386661099708 -0.01438"/>
    <axis xyz="1 0 0"/>
    <parent link="wheel_1"/>
    <child link="roller_1_0_1"/>
  </joint>
  <link name="roller_1_0_2">
    <collision>
      <origin rpy="0 0 0" xyz="0 0 0"/>
      <geometry>
        <sphere radius="0.0095"/>
      </geometry>
    </collision>
    <inertial>
      <origin rpy="0 0 0" xyz="0 0 0"/>
      <mass value="0.0035913640018287317"/>
      <inertia ixx="1.2964824046601722e-07" ixy="0" ixz="0" iyy="1.2964824046601722e-07" iyz="0" izz="1.2964824046601722e-07"/>
    </inertial>
  </link>
  <joint name="roller_1_0_2_joint" type="continuous">
    <origin rpy="0 0 -1.3962634015954636" xyz="0.04136192562651274 0.0072932234620110776 -0.01438"/>
    <axis xyz="1 0 0"/>
    <parent link="wheel_1"/>
    <child link="roller_1_0_2"/>
  </joint>
  <link name="roller_1_0_3">
    <collision>
      <origin rpy="0 0 0" xyz="0 0 0"/>
      <geometry>
        <sphere radius="0.0095"/>
      </geometry>
    </collision>
    <inertial>
      <origin rpy="0 0 0" xyz="0 0 0"/>
      <mass value="0.0035913640018287317"/>
      <inertia ixx="1.2964824046601722e-07" ixy="0" ixz="0" iyy="1.2964824046601722e-07" iyz="0" izz="1.2964824046601722e-07"/>
    </inertial>
  </link>
  <joint name="roller_1_0_3_joint" type="continuous">
    <origin rpy="0 0 -2.0943951023931953" xyz="0.036373066958946425 -0.02099999999999999 -0.01438"/>
    <axis xyz="1 0 0"/>
    <parent link="wheel_1"/>
    <child link="roller_1_0_3"/>
  </joint>
  <link name="roller_1_0_4">
    <collision>
      <origin rpy="0 0 0" xyz="0 0 0"/>
      <geometry>
        <sphere radius="0.0095"/>
      </geometry>
    </collision>
    <inertial>
      <origin rpy="0 0 0" xyz="0 0 0"/>
      <mass value="0.0035913640018287317"/>
      <inertia ixx="1.2964824046601722e-07" ixy="0" ixz="0" iyy="1.2964824046601722e-07" iyz="0" izz="1.2964824046601722e-07"/>
    </inertial>
  </link>
  <joint name="roller_1_0_4_joint" type="continuous">
    <origin rpy="0 0 -2.792526803190927" xyz="0.014364846019678093 -0.03946709007300815 -0.01438"/>
    <axis xyz="1 0 0"/>
    <parent link="wheel_1"/>
    <child link="roller_1_0_4"/>
  </joint>
  <link name="roller_1_0_5">
    <collision>
      <origin rpy="0 0 0" xyz="0 0 0"/>
      <geometry>
        <sphere radius="0.0095"/>
      </geometry>
    </collision>
    <inertial>
      <origin rpy="0 0 0" xyz="0 0 0"/>
      <mass value="0.0035913640018287317"/>
      <inertia ixx="1.2964824046601722e-07" ixy="0" ixz="0" iyy="1.2964824046601722e-07" iyz="0" izz="1.2964824046601722e-07"/>
    </inertial>
  </link>
  <joint name="roller_1_0_5_joint" type="continuous">
    <origin rpy="0 0 -3.490658503988659" xyz="-0.014364846019678084 -0.03946709007300816 -0.01438"/>
    <axis xyz="1 0 0"/>
    <parent link="wheel_1"/>
    <child link="roller_1_0_5"/>
  </joint>
  <link name="roller_1_0_6">
    <collision>
      <origin rpy="0 0 0" xyz="0 0 0"/>
      <geometry>
        <sphere radius="0.0095"/>
      </geometry>
    </collision>
    <inertial>
      <origin rpy="0 0 0" xyz="0 0 0"/>
      <mass value="0.0035913640018287317"/>
      <inertia ixx="1.2964824046601722e-07" ixy="0" ixz="0" iyy="1.2964824046601722e-07" iyz="0" izz="1.2964824046601722e-07"/>
    </inertial>
  </link>
  <joint name="roller_1_0_6_joint" type="continuous">
    <origin rpy="0 0 -4.1887902047863905" xyz="-0.03637306695894641 -0.02100000000000002 -0.01438"/>
    <axis xyz="1 0 0"/>
    <parent link="wheel_1"/>
    <child link="roller_1_0_6"/>
  </joint>
  <link name="roller_1_0_7">
    <collision>
      <origin rpy="0 0 0" xyz="0 0 0"/>
      <geometry>
        <sphere radius="0.0095"/>
      </geometry>
    </collision>
    <inertial>
      <origin rpy="0 0 0" xyz="0 0 0"/>
      <mass value="0.0035913640018287317"/>
      <inertia ixx="1.2964824046601722e-07" ixy="0" ixz="0" iyy="1.2964824046601722e-07" iyz="0" izz="1.2964824046601722e-07"/>
    </inertial>
  </link>
  <joint name="roller_1_0_7_joint" type="continuous">
    <origin rpy="0 0 -4.886921905584122" xyz="-0.041361925626512745 0.007293223462011059 -0.01438"/>
    <axis xyz="1 0 0"/>
    <parent link="wheel_1"/>
    <child link="roller_1_0_7"/>
  </joint>
  <link name="roller_1_0_8">
    <collision>
      <origin rpy="0 0 0" xyz="0 0 0"/>
      <geometry>
        <sphere radius="0.0095"/>
      </geometry>
    </collision>
    <inertial>
      <origin rpy="0 0 0" xyz="0 0 0"/>
      <mass value="0.0035913640018287317"/>
      <inertia ixx="1.2964824046601722e-07" ixy="0" ixz="0" iyy="1.2964824046601722e-07" iyz="0" izz="1.2964824046601722e-07"/>
    </inertial>
  </link>
  <joint name="roller_1_0_8_joint" type="continuous">
    <origin rpy="0 0 -5.585053606381854" xyz="-0.026997079606834663 0.03217386661099707 -0.01438"/>
    <axis xyz="1 0 0"/>
    <parent link="wheel_1"/>
    <child link="roller_1_0_8"/>
  </joint>
  <link name="roller_1_1_0">
    <collision>
      <origin rpy="0 0 0" xyz="0 0 0"/>
      <geometry>
        <sphere radius="0.0095"/>
      </geometry>
    </collision>
    <inertial>
      <origin rpy="0 0 0" xyz="0 0 0"/>
      <mass value="0.0035913640018287317"/>
      <inertia ixx="1.2964824046601722e-07" ixy="0" ixz="0" iyy="1.2964824046601722e-07" iyz="0" izz="1.2964824046601722e-07"/>
    </inertial>
  </link>
  <joint name="roller_1_1_0_joint" type="continuous">
    <origin rpy="0 0 -0.3490658503988659" xyz="0.014364846019678086 0.03946709007300816 0.01438"/>
    <axis xyz="1 0 0"/>
    <parent link="wheel_1"/>
    <child link="roller_1_1_0"/>
  </joint>
  <link name="roller_1_1_1">
    <collision>
      <origin rpy="0 0 0" xyz="0 0 0"/>
      <geometry>
        <sphere radius="0.0095"/>
      </geometry>
    </collision>
    <inertial>
      <origin rpy="0 0 0" xyz="0 0 0"/>
      <mass value="0.0035913640018287317"/>
      <inertia ixx="1.2964824046601722e-07" ixy="0" ixz="0" iyy="1.2964824046601722e-07" iyz="0" izz="1.2964824046601722e-07"/>
    </inertial>
  </link>
  <joint name="roller_1_1_1_joint" type="continuous">
    <origin rpy="0 0 -1.0471975511965976" xyz="0.036373066958946425 0.021000000000000005 0.01438"/>
    <axis xyz="1 0 0"/>
    <parent link="wheel_1"/>
    <child link="roller_1_1_1"/>
  </joint>
  <link name="roller_1_1_2">
    <collision>
      <origin rpy="0 0 0" xyz="0 0 0"/>
      <geometry>
        <sphere radius="0.0095"/>
      </geometry>
    </collision>
    <inertial>
      <origin rpy="0 0 0" xyz="0 0 0"/>
      <mass value="0.0035913640018287317"/>
      <inertia ixx="1.2964824046601722e-07" ixy="0" ixz="0" iyy="1.2964824046601722e-07" iyz="0" izz="1.2964824046601722e-07"/>
    </inertial>
  </link>
  <joint name="roller_1_1_2_joint" type="continuous">
    <origin rpy="0 0 -1.7453292519943295" xyz="0.04136192562651274 -0.007293223462011073 0.01438"/>
    <axis xyz="1 0 0"/>
    <parent link="wheel_1"/>
    <child link="roller_1_1_2"/>
  </joint>
  <link name="roller_1_1_3">
    <collision>
      <origin rpy="0 0 0" xyz="0 0 0"/>
      <geometry>
        <sphere radius="0.0095"/>
      </geometry>
    </collision>
    <inertial>
      <origin rpy="0 0 0" xyz="0 0 0"/>
      <mass value="0.0035913640018287317"/>
      <inertia ixx="1.2964824046601722e-07" ixy="0" ixz="0" iyy="1.2964824046601722e-07" iyz="0" izz="1.2964824046601722e-07"/>
    </inertial>
  </link>
  <joint name="roller_1_1_3_joint" type="continuous">
    <origin rpy="0 0 -2.443460952792061" xyz="0.02699707960683466 -0.032173866610997075 0.01438"/>
    <axis xyz="1 0 0"/>
    <parent link="wheel_1"/>
    <child link="roller_1_1_3"/>
  </joint>
  <link name="roller_1_1_4">
    <collision>
      <origin rpy="0 0 0" xyz="0 0 0"/>
      <geometry>
        <sphere radius="0.0095"/>
      </geometry>
    </collision>
    <inertial>
      <origin rpy="0 0 0" xyz="0 0 0"/>
      <mass value="0.0035913640018287317"/>
      <inertia ixx="1.2964824046601722e-07" ixy="0" ixz="0" iyy="1.2964824046601722e-07" iyz="0" izz="1.2964824046601722e-07"/>
    </inertial>
  </link>
  <joint name="roller_1_1_4_joint" type="continuous">
    <origin rpy="0 0 -3.141592653589793" xyz="5.143516556418884e-18 -0.042 0.01438"/>
    <axis xyz="1 0 0"/>
    <parent link="wheel_1"/>
    <child link="roller_1_1_4"/>
  </joint>
  <link name="roller_1_1_5">
    <collision>
      <origin rpy="0 0 0" xyz="0 0 0"/>
      <geometry>
        <sphere radius="0.0095"/>
      </geometry>
    </collision>
    <inertial>
      <origin rpy="0 0 0" xyz="0 0 0"/>
      <mass value="0.0035913640018287317"/>
      <inertia ixx="1.2964824046601722e-07" ixy="0" ixz="0" iyy="1.2964824046601722e-07" iyz="0" izz="1.2964824046601722e-07"/>
    </inertial>
  </link>
  <joint name="roller_1_1_5_joint" type="continuous">
    <origin rpy="0 0 -3.839724354387525" xyz="-0.02699707960683465 -0.03217386661099708 0.01438"/>
    <axis xyz="1 0 0"/>
    <parent link="wheel_1"/>
    <child link="roller_1_1_5"/>
  </joint>
  <link name="roller_1_1_6">
    <collision>
      <origin rpy="0 0 0" xyz="0 0 0"/>
      <geometry>
        <sphere radius="0.0095"/>
      </geometry>
    </collision>
    <inertial>
      <origin rpy="0 0 0" xyz="0 0 0"/>
      <mass value="0.0035913640018287317"/>
      <inertia ixx="1.2964824046601722e-07" ixy="0" ixz="0" iyy="1.2964824046601722e-07" iyz="0" izz="1.2964824046601722e-07"/>
    </inertial>
  </link>
  <joint name="roller_1_1_6_joint" type="continuous">
    <origin rpy="0 0 -4.537856055185257" xyz="-0.04136192562651274 -0.007293223462011074 0.01438"/>
    <axis xyz="1 0 0"/>
    <parent link="wheel_1"/>
    <child link="roller_1_1_6"/>
  </joint>
  <link name="roller_1_1_7">
    <collision>
      <origin rpy="0 0 0" xyz="0 0 0"/>
      <geometry>
        <sphere radius="0.0095"/>
      </geometry>
    </collision>
    <inertial>
      <origin rpy="0 0 0" xyz="0 0 0"/>
      <mass value="0.0035913640018287317"/>
      <inertia ixx="1.2964824046601722e-07" ixy="0" ixz="0" iyy="1.2964824046601722e-07" iyz="0" izz="1.2964824046601722e-07"/>
    </inertial>
  </link>
  <joint name="roller_1_1_7_joint" type="continuous">
    <origin rpy="0 0 -5.235987755982989" xyz="-0.036373066958946425 0.021000000000000005 0.01438"/>
    <axis xyz="1 0 0"/>
    <parent link="wheel_1"/>
    <child link="roller_1_1_7"/>
  </joint>
  <link name="roller_1_1_8">
    <collision>
      <origin rpy="0 0 0" xyz="0 0 0"/>
      <geometry>
        <sphere radius="0.0095"/>
      </geometry>
    </collision>
    <inertial>
      <origin rpy="0 0 0" xyz="0 0 0"/>
      <mass value="0.0035913640018287317"/>
      <inertia ixx="1.2964824046601722e-07" ixy="0" ixz="0" iyy="1.2964824046601722e-07" iyz="0" izz="1.2964824046601722e-07"/>
    </inertial>
  </link>
  <joint name="roller_1_1_8_joint" type="continuous">
    <origin rpy="0 0 -5.93411945678072" xyz="-0.014364846019678117 0.039467090073008144 0.01438"/>
    <axis xyz="1 0 0"/>
    <parent link="wheel_1"/>
    <child link="roller_1_1_8"/>
  </joint>
  <link name="motor_mount_2">
    <visual>
      <geometry>
        <mesh filename="package://meshes/motor_mount.dae" scale="1 1 1"/>
      </geometry>
    </visual>
  </link>
  <joint name="motor_mount_2_joint" type="fixed">
    <origin rpy="0 0 1.0471975511965976" xyz="0.047500000000000014 0.08227241335952167 0"/>
    <parent link="base_plate"/>
    <child link="motor_mount_2"/>
  </joint>
  <link name="motor_2">
    <visual>
      <geometry>
        <mesh filename="package://meshes/ZGX38REE.dae" scale="1 1 1"/>
      </geometry>
    </visual>
    <collision>
      <origin rpy="0 0 0" xyz="0 0 0"/>
      <geometry>
        <cylinder length="0.11" radius="0.019"/>
      </geometry>
    </collision>
    <inertial>
      <origin rpy="0 0 0" xyz="0 0 0"/>
      <mass value="0.6144067730496996"/>
      <inertia ixx="0.0006749770407595159" ixy="0" ixz="0" iyy="0.0006749770407595159" iyz="0" izz="0.00011090042253547078"/>
    </inertial>
  </link>
  <joint name="motor_2_joint" type="fixed">
    <origin rpy="0 -0.6981317007977318 0" xyz="-0.033202134613707274 0 -0.003797792545214791"/>
    <parent link="motor_mount_2"/>
    <child link="motor_2"/>
  </joint>
  <link name="wheel_2">
    <visual>
      <geometry>
        <mesh filename="package://meshes/omni_wheel.dae" scale="1 1 1"/>
      </geometry>
    </visual>
    <inertial>
      <origin rpy="0 0 0" xyz="0 0 0"/>
      <mass value="0.30139914330089534"/>
      <inertia ixx="0.00020914934489905617" ixy="0" ixz="0" iyy="0.00020914934489905617" iyz="0" izz="0.00037674892912611924"/>
    </inertial>
  </link>
  <joint name="wheel_2_joint" type="continuous">
    <origin rpy="0 0 0" xyz="0 0 -0.10666"/>
    <axis xyz="0 0 -1"/>
    <parent link="motor_2"/>
    <child link="wheel_2"/>
  </joint>
  <link name="roller_2_0_0">
    <collision>
      <origin rpy="0 0 0" xyz="0 0 0"/>
      <geometry>
        <sphere radius="0.0095"/>
      </geometry>
    </collision>
    <inertial>
      <origin rpy="0 0 0" xyz="0 0 0"/>
      <mass value="0.0035913640018287317"/>
      <inertia ixx="1.2964824046601722e-07" ixy="0" ixz="0" iyy="1.2964824046601722e-07" iyz="0" izz="1.2964824046601722e-07"/>
    </inertial>
  </link>
  <joint name="roller_2_0_0_joint" type="continuous">
    <origin rpy="0 0 -0.0" xyz="0.0 0.042 -0.01438"/>
    <axis xyz="1 0 0"/>
    <parent link="wheel_2"/>
    <child link="roller_2_0_0"/>
  </joint>
  <link name="roller_2_0_1">
    <collision>
      <origin rpy="0 0 0" xyz="0 0 0"/>
      <geometry>
        <sphere radius="0.0095"/>
      </geometry>
    </collision>
    <inertial>
      <origin rpy="0 0 0" xyz="0 0 0"/>
      <mass value="0.0035913640018287317"/>
      <inertia ixx="1.2964824046601722e-07" ixy="0" ixz="0" iyy="1.2964824046601722e-07" iyz="0" izz="1.2964824046601722e-07"/>
    </inertial>
  </link>
  <joint name="roller_2_0_1_joint" type="continuous">
    <origin rpy="0 0 -0.6981317007977318" xyz="0.02699707960683465 0.03217386661099708 -0.01438"/>
    <axis xyz="1 0 0"/>
    <parent link="wheel_2"/>
    <child link="roller_2_0_1"/>
  </joint>
  <link name="roller_2_0_2">
    <collision>
      <origin rpy="0 0 0" xyz="0 0 0"/>
      <geometry>
        <sphere radius="0.0095"/>
      </geometry>
    </collision>
    <inertial>
      <origin rpy="0 0 0" xyz="0 0 0"/>
      <mass value="0.0035913640018287317"/>
      <inertia ixx="1.2964824046601722e-07" ixy="0" ixz="0" iyy="1.2964824046601722e-07" iyz="0" izz="1.2964824046601722e-07"/>
    </inertial>
  </link>
  <joint name="roller_2_0_2_joint" type="continuous">
    <origin rpy="0 0 -1.3962634015954636" xyz="0.04136192562651274 0.0072932234620110776 -0.01438"/>
    <axis xyz="1 0 0"/>
    <parent link="wheel_2"/>
    <child link="roller_2_0_2"/>
  </joint>
  <link name="roller_2_0_3">
    <collision>
      <origin rpy="0 0 0" xyz="0 0 0"/>
      <geometry>
        <sphere radius="0.0095"/>
      </geometry>
    </collision>
    <inertial>
      <origin rpy="0 0 0" xyz="0 0 0"/>
      <mass value="0.0035913640018287317"/>
      <inertia ixx="1.2964824046601722e-07" ixy="0" ixz="0" iyy="1.2964824046601722e-07" iyz="0" izz="1.2964824046601722e-07"/>
    </inertial>
  </link>
  <joint name="roller_2_0_3_joint" type="continuous">
    <origin rpy="0 0 -2.0943951023931953" xyz="0.036373066958946425 -0.02099999999999999 -0.01438"/>
    <axis xyz="1 0 0"/>
    <parent link="wheel_2"/>
    <child link="roller_2_0_3"/>
  </joint>
  <link name="roller_2_0_4">
    <collision>
      <origin rpy="0 0 0" xyz="0 0 0"/>
      <geometry>
        <sphere radius="0.0095"/>
      </geometry>
    </collision>
    <inertial>
      <origin rpy="0 0 0" xyz="0 0 0"/>
      <mass value="0.0035913640018287317"/>
      <inertia ixx="1.2964824046601722e-07" ixy="0" ixz="0" iyy="1.2964824046601722e-07" iyz="0" izz="1.2964824046601722e-07"/>
    </inertial>
  </link>
  <joint name="roller_2_0_4_joint" type="continuous">
    <origin rpy="0 0 -2.792526803190927" xyz="0.014364846019678093 -0.03946709007300815 -0.01438"/>
    <axis xyz="1 0 0"/>
    <parent link="wheel_2"/>
    <child link="roller_2_0_4"/>
  </joint>
  <link name="roller_2_0_5">
    <collision>
      <origin rpy="0 0 0" xyz="0 0 0"/>
      <geometry>
        <sphere radius="0.0095"/>
      </geometry>
    </collision>
    <inertial>
      <origin rpy="0 0 0" xyz="0 0 0"/>
      <mass value="0.0035913640018287317"/>
      <inertia ixx="1.2964824046601722e-07" ixy="0" ixz="0" iyy="1.2964824046601722e-07" iyz="0" izz="1.2964824046601722e-07"/>
    </inertial>
  </link>
  <joint name="roller_2_0_5_joint" type="continuous">
    <origin rpy="0 0 -3.490658503988659" xyz="-0.014364846019678084 -0.03946709007300816 -0.01438"/>
    <axis xyz="1 0 0"/>
    <parent link="wheel_2"/>
    <child link="roller_2_0_5"/>
  </joint>
  <link name="roller_2_0_6">
    <collision>
      <origin rpy="0 0 0" xyz="0 0 0"/>
      <geometry>
        <sphere radius="0.0095"/>
      </geometry>
    </collision>
    <inertial>
      <origin rpy="0 0 0" xyz="0 0 0"/>
      <mass value="0.0035913640018287317"/>
      <inertia ixx="1.2964824046601722e-07" ixy="0" ixz="0" iyy="1.2964824046601722e-07" iyz="0" izz="1.2964824046601722e-07"/>
    </inertial>
  </link>
  <joint name="roller_2_0_6_joint" type="continuous">
    <origin rpy="0 0 -4.1887902047863905" xyz="-0.03637306695894641 -0.02100000000000002 -0.01438"/>
    <axis xyz="1 0 0"/>
    <parent link="wheel_2"/>
    <child link="roller_2_0_6"/>
  </joint>
  <link name="roller_2_0_7">
    <collision>
      <origin rpy="0 0 0" xyz="0 0 0"/>
      <geometry>
        <sphere radius="0.0095"/>
      </geometry>
    </collision>
    <inertial>
      <origin rpy="0 0 0" xyz="0 0 0"/>
      <mass value="0.0035913640018287317"/>
      <inertia ixx="1.2964824046601722e-07" ixy="0" ixz="0" iyy="1.2964824046601722e-07" iyz="0" izz="1.2964824046601722e-07"/>
    </inertial>
  </link>
  <joint name="roller_2_0_7_joint" type="continuous">
    <origin rpy="0 0 -4.886921905584122" xyz="-0.041361925626512745 0.007293223462011059 -0.01438"/>
    <axis xyz="1 0 0"/>
    <parent link="wheel_2"/>
    <child link="roller_2_0_7"/>
  </joint>
  <link name="roller_2_0_8">
    <collision>
      <origin rpy="0 0 0" xyz="0 0 0"/>
      <geometry>
        <sphere radius="0.0095"/>
      </geometry>
    </collision>
    <inertial>
      <origin rpy="0 0 0" xyz="0 0 0"/>
      <mass value="0.0035913640018287317"/>
      <inertia ixx="1.2964824046601722e-07" ixy="0" ixz="0" iyy="1.2964824046601722e-07" iyz="0" izz="1.2964824046601722e-07"/>
    </inertial>
  </link>
  <joint name="roller_2_0_8_joint" type="continuous">
    <origin rpy="0 0 -5.585053606381854" xyz="-0.026997079606834663 0.03217386661099707 -0.01438"/>
    <axis xyz="1 0 0"/>
    <parent link="wheel_2"/>
    <child link="roller_2_0_8"/>
  </joint>
  <link name="roller_2_1_0">
    <collision>
      <origin rpy="0 0 0" xyz="0 0 0"/>
      <geometry>
        <sphere radius="0.0095"/>
      </geometry>
    </collision>
    <inertial>
      <origin rpy="0 0 0" xyz="0 0 0"/>
      <mass value="0.0035913640018287317"/>
      <inertia ixx="1.2964824046601722e-07" ixy="0" ixz="0" iyy="1.2964824046601722e-07" iyz="0" izz="1.2964824046601722e-07"/>
    </inertial>
  </link>
  <joint name="roller_2_1_0_joint" type="continuous">
    <origin rpy="0 0 -0.3490658503988659" xyz="0.014364846019678086 0.03946709007300816 0.01438"/>
    <axis xyz="1 0 0"/>
    <parent link="wheel_2"/>
    <child link="roller_2_1_0"/>
  </joint>
  <link name="roller_2_1_1">
    <collision>
      <origin rpy="0 0 0" xyz="0 0 0"/>
      <geometry>
        <sphere radius="0.0095"/>
      </geometry>
    </collision>
    <inertial>
      <origin rpy="0 0 0" xyz="0 0 0"/>
      <mass value="0.0035913640018287317"/>
      <inertia ixx="1.2964824046601722e-07" ixy="0" ixz="0" iyy="1.2964824046601722e-07" iyz="0" izz="1.2964824046601722e-07"/>
    </inertial>
  </link>
  <joint name="roller_2_1_1_joint" type="continuous">
    <origin rpy="0 0 -1.0471975511965976" xyz="0.036373066958946425 0.021000000000000005 0.01438"/>
    <axis xyz="1 0 0"/>
    <parent link="wheel_2"/>
    <child link="roller_2_1_1"/>
  </joint>
  <link name="roller_2_1_2">
    <collision>
      <origin rpy="0 0 0" xyz="0 0 0"/>
      <geometry>
        <sphere radius="0.0095"/>
      </geometry>
    </collision>
    <inertial>
      <origin rpy="0 0 0" xyz="0 0 0"/>
      <mass value="0.0035913640018287317"/>
      <inertia ixx="1.2964824046601722e-07" ixy="0" ixz="0" iyy="1.2964824046601722e-07" iyz="0" izz="1.2964824046601722e-07"/>
    </inertial>
  </link>
  <joint name="roller_2_1_2_joint" type="continuous">
    <origin rpy="0 0 -1.7453292519943295" xyz="0.04136192562651274 -0.007293223462011073 0.01438"/>
    <axis xyz="1 0 0"/>
    <parent link="wheel_2"/>
    <child link="roller_2_1_2"/>
  </joint>
  <link name="roller_2_1_3">
    <collision>
      <origin rpy="0 0 0" xyz="0 0 0"/>
      <geometry>
        <sphere radius="0.0095"/>
      </geometry>
    </collision>
    <inertial>
      <origin rpy="0 0 0" xyz="0 0 0"/>
      <mass value="0.0035913640018287317"/>
      <inertia ixx="1.2964824046601722e-07" ixy="0" ixz="0" iyy="1.2964824046601722e-07" iyz="0" izz="1.2964824046601722e-07"/>
    </inertial>
  </link>
  <joint name="roller_2_1_3_joint" type="continuous">
    <origin rpy="0 0 -2.443460952792061" xyz="0.02699707960683466 -0.032173866610997075 0.01438"/>
    <axis xyz="1 0 0"/>
    <parent link="wheel_2"/>
    <child link="roller_2_1_3"/>
  </joint>
  <link name="roller_2_1_4">
    <collision>
      <origin rpy="0 0 0" xyz="0 0 0"/>
      <geometry>
        <sphere radius="0.0095"/>
      </geometry>
    </collision>
    <inertial>
      <origin rpy="0 0 0" xyz="0 0 0"/>
      <mass value="0.0035913640018287317"/>
      <inertia ixx="1.2964824046601722e-07" ixy="0" ixz="0" iyy="1.2964824046601722e-07" iyz="0" izz="1.2964824046601722e-07"/>
    </inertial>
  </link>
  <joint name="roller_2_1_4_joint" type="continuous">
    <origin rpy="0 0 -3.141592653589793" xyz="5.143516556418884e-18 -0.042 0.01438"/>
    <axis xyz="1 0 0"/>
    <parent link="wheel_2"/>
    <child link="roller_2_1_4"/>
  </joint>
  <link name="roller_2_1_5">
    <collision>
      <origin rpy="0 0 0" xyz="0 0 0"/>
      <geometry>
        <sphere radius="0.0095"/>
      </geometry>
    </collision>
    <inertial>
      <origin rpy="0 0 0" xyz="0 0 0"/>
      <mass value="0.0035913640018287317"/>
      <inertia ixx="1.2964824046601722e-07" ixy="0" ixz="0" iyy="1.2964824046601722e-07" iyz="0" izz="1.2964824046601722e-07"/>
    </inertial>
  </link>
  <joint name="roller_2_1_5_joint" type="continuous">
    <origin rpy="0 0 -3.839724354387525" xyz="-0.02699707960683465 -0.03217386661099708 0.01438"/>
    <axis xyz="1 0 0"/>
    <parent link="wheel_2"/>
    <child link="roller_2_1_5"/>
  </joint>
  <link name="roller_2_1_6">
    <collision>
      <origin rpy="0 0 0" xyz="0 0 0"/>
      <geometry>
        <sphere radius="0.0095"/>
      </geometry>
    </collision>
    <inertial>
      <origin rpy="0 0 0" xyz="0 0 0"/>
      <mass value="0.0035913640018287317"/>
      <inertia ixx="1.2964824046601722e-07" ixy="0" ixz="0" iyy="1.2964824046601722e-07" iyz="0" izz="1.2964824046601722e-07"/>
    </inertial>
  </link>
  <joint name="roller_2_1_6_joint" type="continuous">
    <origin rpy="0 0 -4.537856055185257" xyz="-0.04136192562651274 -0.007293223462011074 0.01438"/>
    <axis xyz="1 0 0"/>
    <parent link="wheel_2"/>
    <child link="roller_2_1_6"/>
  </joint>
  <link name="roller_2_1_7">
    <collision>
      <origin rpy="0 0 0" xyz="0 0 0"/>
      <geometry>
        <sphere radius="0.0095"/>
      </geometry>
    </collision>
    <inertial>
      <origin rpy="0 0 0" xyz="0 0 0"/>
      <mass value="0.0035913640018287317"/>
      <inertia ixx="1.2964824046601722e-07" ixy="0" ixz="0" iyy="1.2964824046601722e-07" iyz="0" izz="1.2964824046601722e-07"/>
    </inertial>
  </link>
  <joint name="roller_2_1_7_joint" type="continuous">
    <origin rpy="0 0 -5.235987755982989" xyz="-0.036373066958946425 0.021000000000000005 0.01438"/>
    <axis xyz="1 0 0"/>
    <parent link="wheel_2"/>
    <child link="roller_2_1_7"/>
  </joint>
  <link name="roller_2_1_8">
    <collision>
      <origin rpy="0 0 0" xyz="0 0 0"/>
      <geometry>
        <sphere radius="0.0095"/>
      </geometry>
    </collision>
    <inertial>
      <origin rpy="0 0 0" xyz="0 0 0"/>
      <mass value="0.0035913640018287317"/>
      <inertia ixx="1.2964824046601722e-07" ixy="0" ixz="0" iyy="1.2964824046601722e-07" iyz="0" izz="1.2964824046601722e-07"/>
    </inertial>
  </link>
  <joint name="roller_2_1_8_joint" type="continuous">
    <origin rpy="0 0 -5.93411945678072" xyz="-0.014364846019678117 0.039467090073008144 0.01438"/>
    <axis xyz="1 0 0"/>
    <parent link="wheel_2"/>
    <child link="roller_2_1_8"/>
  </joint>
</robot>
